Workbook

Sheet הגדרות
A1: ⚙ הגדרות מערכת ניהול כוח אדם במילואים
A3: ◀ תאריך תחילת שבוע | C3: 46096
A4: ← שנה את התאריך בתא C3 לעדכון אוטומטי של כל הגיליונות
A6: ימי השבוע | B6: א׳ | C6: ב׳ | D6: ג׳ | E6: ד׳ | F6: ה׳ | G6: ו׳ | H6: ש׳
B7: =הגדרות!$C$3+0 -> 46096 | C7: =הגדרות!$C$3+1 -> 46097 | D7: =הגדרות!$C$3+2 -> 46098 | E7: =הגדרות!$C$3+3 -> 46099 | F7: =הגדרות!$C$3+4 -> 46100 | G7: =הגדרות!$C$3+5 -> 46101 | H7: =הגדרות!$C$3+6 -> 46102
A9: משמרות
A10: בוקר | B10: 06:00–14:00
A11: אמצע | B11: 14:00–22:00
A12: ערב | B12: 22:00–06:00
A14: סף התרעת רצף משמרות | C14: 7
A16: מקרא צבעי סטטוס
A17: ✓ מאויש | B17: ⚠ חוסר | C17: ↑ עודף | D17: ⚡ עומס 7+ משמרות
A19: הוראות שימוש
A20: 1. עדכן את תאריך תחילת השבוע בתא C3 — כל הגיליונות יתעדכנו אוטומטית
A21: 2. הזן נתוני בסיס בגיליון נתוני_בסיס: מחלקות, תפקידים, עובדים, יועצים ותקנים
A22: 3. הזן שיבוצים יומיים בגיליון שיבוץ — תקן, שובצו, פער וסטטוס מחושבים אוטומטית
A23: 4. צפה בלוחות המשמרות, הסיכומים ודשבורד המנהלים לתמונת מצב מלאה
A24: 5. גיליון התרעות_עומס מסמן אוטומטית עובדים עם 7+ משמרות רצופות
A25: 6. גיליון תחזית מציג תחזית פערים/עודפים לפי נתוני התקן הקיימים

Sheet נתוני_בסיס
A1: 📋 דירקטוריית נתוני בסיס — מחלקות, תפקידים, עובדים, יועצים ותקנים
A2: מחלקות | C2: צוות | D2: מחלקה | F2: תפקידים | H2: שם | I2: מחלקה | J2: צוות | K2: תפקיד | L2: טלפון | M2: הערות | O2: שם יועץ | P2: מחלקה | Q2: תחום | R2: הערות | T2: מחלקה | U2: תפקיד | V2: משמרת | W2: תקן | Y2: כל השמות (עובדים+יועצים)
W3: 0 | Y3: =IFERROR(IF(INDEX(T_Employees[שם],1)="","",INDEX(T_Employees[שם],1)),"")
W4: 0 | Y4: =IFERROR(IF(INDEX(T_Employees[שם],2)="","",INDEX(T_Employees[שם],2)),"")
W5: 0 | Y5: =IFERROR(IF(INDEX(T_Employees[שם],3)="","",INDEX(T_Employees[שם],3)),"")
W6: 0 | Y6: =IFERROR(IF(INDEX(T_Employees[שם],4)="","",INDEX(T_Employees[שם],4)),"")
W7: 0 | Y7: =IFERROR(IF(INDEX(T_Employees[שם],5)="","",INDEX(T_Employees[שם],5)),"")
W8: 0 | Y8: =IFERROR(IF(INDEX(T_Employees[שם],6)="","",INDEX(T_Employees[שם],6)),"")
W9: 0 | Y9: =IFERROR(IF(INDEX(T_Employees[שם],7)="","",INDEX(T_Employees[שם],7)),"")
W10: 0 | Y10: =IFERROR(IF(INDEX(T_Employees[שם],8)="","",INDEX(T_Employees[שם],8)),"")
W11: 0 | Y11: =IFERROR(IF(INDEX(T_Employees[שם],9)="","",INDEX(T_Employees[שם],9)),"")
W12: 0 | Y12: =IFERROR(IF(INDEX(T_Employees[שם],10)="","",INDEX(T_Employees[שם],10)),"")
W13: 0 | Y13: =IFERROR(IF(INDEX(T_Employees[שם],11)="","",INDEX(T_Employees[שם],11)),"")
W14: 0 | Y14: =IFERROR(IF(INDEX(T_Employees[שם],12)="","",INDEX(T_Employees[שם],12)),"")
W15: 0 | Y15: =IFERROR(IF(INDEX(T_Employees[שם],13)="","",INDEX(T_Employees[שם],13)),"")
W16: 0 | Y16: =IFERROR(IF(INDEX(T_Employees[שם],14)="","",INDEX(T_Employees[שם],14)),"")
W17: 0 | Y17: =IFERROR(IF(INDEX(T_Employees[שם],15)="","",INDEX(T_Employees[שם],15)),"")
W18: 0 | Y18: =IFERROR(IF(INDEX(T_Employees[שם],16)="","",INDEX(T_Employees[שם],16)),"")
W19: 0 | Y19: =IFERROR(IF(INDEX(T_Employees[שם],17)="","",INDEX(T_Employees[שם],17)),"")
W20: 0 | Y20: =IFERROR(IF(INDEX(T_Employees[שם],18)="","",INDEX(T_Employees[שם],18)),"")
W21: 0 | Y21: =IFERROR(IF(INDEX(T_Employees[שם],19)="","",INDEX(T_Employees[שם],19)),"")
W22: 0 | Y22: =IFERROR(IF(INDEX(T_Employees[שם],20)="","",INDEX(T_Employees[שם],20)),"")
W23: 0 | Y23: =IFERROR(IF(INDEX(T_Employees[שם],21)="","",INDEX(T_Employees[שם],21)),"")
W24: 0 | Y24: =IFERROR(IF(INDEX(T_Employees[שם],22)="","",INDEX(T_Employees[שם],22)),"")
W25: 0 | Y25: =IFERROR(IF(INDEX(T_Employees[שם],23)="","",INDEX(T_Employees[שם],23)),"")
W26: 0 | Y26: =IFERROR(IF(INDEX(T_Employees[שם],24)="","",INDEX(T_Employees[שם],24)),"")
W27: 0 | Y27: =IFERROR(IF(INDEX(T_Employees[שם],25)="","",INDEX(T_Employees[שם],25)),"")
W28: 0 | Y28: =IFERROR(IF(INDEX(T_Employees[שם],26)="","",INDEX(T_Employees[שם],26)),"")
W29: 0 | Y29: =IFERROR(IF(INDEX(T_Employees[שם],27)="","",INDEX(T_Employees[שם],27)),"")
W30: 0 | Y30: =IFERROR(IF(INDEX(T_Employees[שם],28)="","",INDEX(T_Employees[שם],28)),"")
W31: 0 | Y31: =IFERROR(IF(INDEX(T_Employees[שם],29)="","",INDEX(T_Employees[שם],29)),"")
W32: 0 | Y32: =IFERROR(IF(INDEX(T_Employees[שם],30)="","",INDEX(T_Employees[שם],30)),"")
W33: 0 | Y33: =IFERROR(IF(INDEX(T_Employees[שם],31)="","",INDEX(T_Employees[שם],31)),"")
W34: 0 | Y34: =IFERROR(IF(INDEX(T_Employees[שם],32)="","",INDEX(T_Employees[שם],32)),"")
W35: 0 | Y35: =IFERROR(IF(INDEX(T_Employees[שם],33)="","",INDEX(T_Employees[שם],33)),"")
W36: 0 | Y36: =IFERROR(IF(INDEX(T_Employees[שם],34)="","",INDEX(T_Employees[שם],34)),"")
W37: 0 | Y37: =IFERROR(IF(INDEX(T_Employees[שם],35)="","",INDEX(T_Employees[שם],35)),"")
W38: 0 | Y38: =IFERROR(IF(INDEX(T_Employees[שם],36)="","",INDEX(T_Employees[שם],36)),"")
W39: 0 | Y39: =IFERROR(IF(INDEX(T_Employees[שם],37)="","",INDEX(T_Employees[שם],37)),"")
W40: 0 | Y40: =IFERROR(IF(INDEX(T_Employees[שם],38)="","",INDEX(T_Employees[שם],38)),"")
...

Sheet שיבוץ
A1: 📋 לוח שיבוץ — הזן כאן את השיבוצים היומיים
A2: תאריך | B2: משמרת | C2: מחלקה | D2: צוות | E2: תפקיד | F2: שם | G2: סוג | H2: תקן | I2: שובצו | J2: פער | K2: חוסר | L2: עודף | M2: סטטוס | N2: יום שבוע | O2: מדד רצף
G3: =IFERROR(IF($F3="","",IF(COUNTIF(נתוני_בסיס!$O$3:$O$52,$F3)>0,"יועץ","עובד")),"") | H3: =IFERROR(IF($C3="",0,SUMPRODUCT((T_Standards[מחלקה]=$C3)*(T_Standards[תפקיד]=$E3)*(T_Standards[משמרת]=$B3)*T_Standards[תקן])),0) -> 0 | I3: =IFERROR(IF($A3="",0,COUNTIFS($A$3:$A$2000,$A3,$B$3:$B$2000,$B3,$C$3:$C$2000,$C3,$E$3:$E$2000,$E3)),0) -> 0 | J3: =IFERROR($H3-$I3,0) -> 0 | K3: =IFERROR(MAX(0,$J3),0) -> 0 | L3: =IFERROR(MAX(0,-$J3),0) -> 0 | M3: =IFERROR(IF($A3="","",IF($J3=0,"✓ מאויש",IF($J3>0,"⚠ חוסר","↑ עודף"))),"") | N3: =IFERROR(IF($A3="","",CHOOSE(WEEKDAY($A3,2),"ב׳","ג׳","ד׳","ה׳","ו׳","ש׳","א׳")),"") | O3: =IFERROR(IF($A3="","",($A3-DATE(2024,1,1))*3+IF($B3="בוקר",1,IF($B3="אמצע",2,3))),"")

Sheet לוח_יומי_כללי
A1: 📅 לוח משמרות יומי — כל המחלקות יחד
A3: תאריך מוצג | B3: =הגדרות!$C$3 -> 46096 | C3: ← ניתן לשנות ידנית לתאריך אחר
A5: מחלקה | B5: בוקר | F5: אמצע | J5: ערב | N5: סיכום יומי
B6: תקן | C6: שובצו | D6: פער | E6: סטטוס | F6: תקן | G6: שובצו | H6: פער | I6: סטטוס | J6: תקן | K6: שובצו | L6: פער | M6: סטטוס | N6: תקן | O6: שובצו | P6: פער | Q6: סטטוס
A7: =IFERROR(INDEX(T_Depts[מחלקה],1),"") | B7: =IFERROR(SUMPRODUCT((T_Standards[מחלקה]=$A7)*(T_Standards[משמרת]="בוקר")*T_Standards[תקן]),0) -> 0 | C7: =IFERROR(COUNTIFS(T_Assign[תאריך],$B$3,T_Assign[משמרת],"בוקר",T_Assign[מחלקה],$A7),0) -> 0 | D7: =IFERROR(B7-C7,0) -> 0 | E7: =IFERROR(IF($A7="","",IF(D7=0,"✓",IF(D7>0,"⚠","↑"))),"") | F7: =IFERROR(SUMPRODUCT((T_Standards[מחלקה]=$A7)*(T_Standards[משמרת]="אמצע")*T_Standards[תקן]),0) -> 0 | G7: =IFERROR(COUNTIFS(T_Assign[תאריך],$B$3,T_Assign[משמרת],"אמצע",T_Assign[מחלקה],$A7),0) -> 0 | H7: =IFERROR(F7-G7,0) -> 0 | I7: =IFERROR(IF($A7="","",IF(H7=0,"✓",IF(H7>0,"⚠","↑"))),"") | J7: =IFERROR(SUMPRODUCT((T_Standards[מחלקה]=$A7)*(T_Standards[משמרת]="ערב")*T_Standards[תקן]),0) -> 0 | K7: =IFERROR(COUNTIFS(T_Assign[תאריך],$B$3,T_Assign[משמרת],"ערב",T_Assign[מחלקה],$A7),0) -> 0 | L7: =IFERROR(J7-K7,0) -> 0 | M7: =IFERROR(IF($A7="","",IF(L7=0,"✓",IF(L7>0,"⚠","↑"))),"") | N7: =IFERROR(SUM(B7,F7,J7),0) -> 0 | O7: =IFERROR(SUM(C7,G7,K7),0) -> 0 | P7: =IFERROR(N7-O7,0) -> 0 | Q7: =IFERROR(IF($A7="","",IF(P7=0,"✓ מאויש",IF(P7>0,"⚠ חוסר","↑ עודף"))),"")
A8: =IFERROR(INDEX(T_Depts[מחלקה],2),"") | B8: =IFERROR(SUMPRODUCT((T_Standards[מחלקה]=$A8)*(T_Standards[משמרת]="בוקר")*T_Standards[תקן]),0) -> 0 | C8: =IFERROR(COUNTIFS(T_Assign[תאריך],$B$3,T_Assign[משמרת],"בוקר",T_Assign[מחלקה],$A8),0) -> 0 | D8: =IFERROR(B8-C8,0) -> 0 | E8: =IFERROR(IF($A8="","",IF(D8=0,"✓",IF(D8>0,"⚠","↑"))),"") | F8: =IFERROR(SUMPRODUCT((T_Standards[מחלקה]=$A8)*(T_Standards[משמרת]="אמצע")*T_Standards[תקן]),0) -> 0 | G8: =IFERROR(COUNTIFS(T_Assign[תאריך],$B$3,T_Assign[משמרת],"אמצע",T_Assign[מחלקה],$A8),0) -> 0 | H8: =IFERROR(F8-G8,0) -> 0 | I8: =IFERROR(IF($A8="","",IF(H8=0,"✓",IF(H8>0,"⚠","↑"))),"") | J8: =IFERROR(SUMPRODUCT((T_Standards[מחלקה]=$A8)*(T_Standards[משמרת]="ערב")*T_Standards[תקן]),0) -> 0 | K8: =IFERROR(COUNTIFS(T_Assign[תאריך],$B$3,T_Assign[משמרת],"ערב",T_Assign[מחלקה],$A8),0) -> 0 | L8: =IFERROR(J8-K8,0) -> 0 | M8: =IFERROR(IF($A8="","",IF(L8=0,"✓",IF(L8>0,"⚠","↑"))),"") | N8: =IFERROR(SUM(B8,F8,J8),0) -> 0 | O8: =IFERROR(SUM(C8,G8,K8),0) -> 0 | P8: =IFERROR(N8-O8,0) -> 0 | Q8: =IFERROR(IF($A8="","",IF(P8=0,"✓ מאויש",IF(P8>0,"⚠ חוסר","↑ עודף"))),"")
A9: =IFERROR(INDEX(T_Depts[מחלקה],3),"") | B9: =IFERROR(SUMPRODUCT((T_Standards[מחלקה]=$A9)*(T_Standards[משמרת]="בוקר")*T_Standards[תקן]),0) -> 0 | C9: =IFERROR(COUNTIFS(T_Assign[תאריך],$B$3,T_Assign[משמרת],"בוקר",T_Assign[מחלקה],$A9),0) -> 0 | D9: =IFERROR(B9-C9,0) -> 0 | E9: =IFERROR(IF($A9="","",IF(D9=0,"✓",IF(D9>0,"⚠","↑"))),"") | F9: =IFERROR(SUMPRODUCT((T_Standards[מחלקה]=$A9)*(T_Standards[משמרת]="אמצע")*T_Standards[תקן]),0) -> 0 | G9: =IFERROR(COUNTIFS(T_Assign[תאריך],$B$3,T_Assign[משמרת],"אמצע",T_Assign[מחלקה],$A9),0) -> 0 | H9: =IFERROR(F9-G9,0) -> 0 | I9: =IFERROR(IF($A9="","",IF(H9=0,"✓",IF(H9>0,"⚠","↑"))),"") | J9: =IFERROR(SUMPRODUCT((T_Standards[מחלקה]=$A9)*(T_Standards[משמרת]="ערב")*T_Standards[תקן]),0) -> 0 | K9: =IFERROR(COUNTIFS(T_Assign[תאריך],$B$3,T_Assign[משמרת],"ערב",T_Assign[מחלקה],$A9),0) -> 0 | L9: =IFERROR(J9-K9,0) -> 0 | M9: =IFERROR(IF($A9="","",IF(L9=0,"✓",IF(L9>0,"⚠","↑"))),"") | N9: =IFERROR(SUM(B9,F9,J9),0) -> 0 | O9: =IFERROR(SUM(C9,G9,K9),0) -> 0 | P9: =IFERROR(N9-O9,0) -> 0 | Q9: =IFERROR(IF($A9="","",IF(P9=0,"✓ מאויש",IF(P9>0,"⚠ חוסר","↑ עודף"))),"")
A10: =IFERROR(INDEX(T_Depts[מחלקה],4),"") | B10: =IFERROR(SUMPRODUCT((T_Standards[מחלקה]=$A10)*(T_Standards[משמרת]="בוקר")*T_Standards[תקן]),0) -> 0 | C10: =IFERROR(COUNTIFS(T_Assign[תאריך],$B$3,T_Assign[משמרת],"בוקר",T_Assign[מחלקה],$A10),0) -> 0 | D10: =IFERROR(B10-C10,0) -> 0 | E10: =IFERROR(IF($A10="","",IF(D10=0,"✓",IF(D10>0,"⚠","↑"))),"") | F10: =IFERROR(SUMPRODUCT((T_Standards[מחלקה]=$A10)*(T_Standards[משמרת]="אמצע")*T_Standards[תקן]),0) -> 0 | G10: =IFERROR(COUNTIFS(T_Assign[תאריך],$B$3,T_Assign[משמרת],"אמצע",T_Assign[מחלקה],$A10),0) -> 0 | H10: =IFERROR(F10-G10,0) -> 0 | I10: =IFERROR(IF($A10="","",IF(H10=0,"✓",IF(H10>0,"⚠","↑"))),"") | J10: =IFERROR(SUMPRODUCT((T_Standards[מחלקה]=$A10)*(T_Standards[משמרת]="ערב")*T_Standards[תקן]),0) -> 0 | K10: =IFERROR(COUNTIFS(T_Assign[תאריך],$B$3,T_Assign[משמרת],"ערב",T_Assign[מחלקה],$A10),0) -> 0 | L10: =IFERROR(J10-K10,0) -> 0 | M10: =IFERROR(IF($A10="","",IF(L10=0,"✓",IF(L10>0,"⚠","↑"))),"") | N10: =IFERROR(SUM(B10,F10,J10),0) -> 0 | O10: =IFERROR(SUM(C10,G10,K10),0) -> 0 | P10: =IFERROR(N10-O10,0) -> 0 | Q10: =IFERROR(IF($A10="","",IF(P10=0,"✓ מאויש",IF(P10>0,"⚠ חוסר","↑ עודף"))),"")
A11: =IFERROR(INDEX(T_Depts[מחלקה],5),"") | B11: =IFERROR(SUMPRODUCT((T_Standards[מחלקה]=$A11)*(T_Standards[משמרת]="בוקר")*T_Standards[תקן]),0) -> 0 | C11: =IFERROR(COUNTIFS(T_Assign[תאריך],$B$3,T_Assign[משמרת],"בוקר",T_Assign[מחלקה],$A11),0) -> 0 | D11: =IFERROR(B11-C11,0) -> 0 | E11: =IFERROR(IF($A11="","",IF(D11=0,"✓",IF(D11>0,"⚠","↑"))),"") | F11: =IFERROR(SUMPRODUCT((T_Standards[מחלקה]=$A11)*(T_Standards[משמרת]="אמצע")*T_Standards[תקן]),0) -> 0 | G11: =IFERROR(COUNTIFS(T_Assign[תאריך],$B$3,T_Assign[משמרת],"אמצע",T_Assign[מחלקה],$A11),0) -> 0 | H11: =IFERROR(F11-G11,0) -> 0 | I11: =IFERROR(IF($A11="","",IF(H11=0,"✓",IF(H11>0,"⚠","↑"))),"") | J11: =IFERROR(SUMPRODUCT((T_Standards[מחלקה]=$A11)*(T_Standards[משמרת]="ערב")*T_Standards[תקן]),0) -> 0 | K11: =IFERROR(COUNTIFS(T_Assign[תאריך],$B$3,T_Assign[משמרת],"ערב",T_Assign[מחלקה],$A11),0) -> 0 | L11: =IFERROR(J11-K11,0) -> 0 | M11: =IFERROR(IF($A11="","",IF(L11=0,"✓",IF(L11>0,"⚠","↑"))),"") | N11: =IFERROR(SUM(B11,F11,J11),0) -> 0 | O11: =IFERROR(SUM(C11,G11,K11),0) -> 0 | P11: =IFERROR(N11-O11,0) -> 0 | Q11: =IFERROR(IF($A11="","",IF(P11=0,"✓ מאויש",IF(P11>0,"⚠ חוסר","↑ עודף"))),"")
A12: =IFERROR(INDEX(T_Depts[מחלקה],6),"") | B12: =IFERROR(SUMPRODUCT((T_Standards[מחלקה]=$A12)*(T_Standards[משמרת]="בוקר")*T_Standards[תקן]),0) -> 0 | C12: =IFERROR(COUNTIFS(T_Assign[תאריך],$B$3,T_Assign[משמרת],"בוקר",T_Assign[מחלקה],$A12),0) -> 0 | D12: =IFERROR(B12-C12,0) -> 0 | E12: =IFERROR(IF($A12="","",IF(D12=0,"✓",IF(D12>0,"⚠","↑"))),"") | F12: =IFERROR(SUMPRODUCT((T_Standards[מחלקה]=$A12)*(T_Standards[משמרת]="אמצע")*T_Standards[תקן]),0) -> 0 | G12: =IFERROR(COUNTIFS(T_Assign[תאריך],$B$3,T_Assign[משמרת],"אמצע",T_Assign[מחלקה],$A12),0) -> 0 | H12: =IFERROR(F12-G12,0) -> 0 | I12: =IFERROR(IF($A12="","",IF(H12=0,"✓",IF(H12>0,"⚠","↑"))),"") | J12: =IFERROR(SUMPRODUCT((T_Standards[מחלקה]=$A12)*(T_Standards[משמרת]="ערב")*T_Standards[תקן]),0) -> 0 | K12: =IFERROR(COUNTIFS(T_Assign[תאריך],$B$3,T_Assign[משמרת],"ערב",T_Assign[מחלקה],$A12),0) -> 0 | L12: =IFERROR(J12-K12,0) -> 0 | M12: =IFERROR(IF($A12="","",IF(L12=0,"✓",IF(L12>0,"⚠","↑"))),"") | N12: =IFERROR(SUM(B12,F12,J12),0) -> 0 | O12: =IFERROR(SUM(C12,G12,K12),0) -> 0 | P12: =IFERROR(N12-O12,0) -> 0 | Q12: =IFERROR(IF($A12="","",IF(P12=0,"✓ מאויש",IF(P12>0,"⚠ חוסר","↑ עודף"))),"")
A13: =IFERROR(INDEX(T_Depts[מחלקה],7),"") | B13: =IFERROR(SUMPRODUCT((T_Standards[מחלקה]=$A13)*(T_Standards[משמרת]="בוקר")*T_Standards[תקן]),0) -> 0 | C13: =IFERROR(COUNTIFS(T_Assign[תאריך],$B$3,T_Assign[משמרת],"בוקר",T_Assign[מחלקה],$A13),0) -> 0 | D13: =IFERROR(B13-C13,0) -> 0 | E13: =IFERROR(IF($A13="","",IF(D13=0,"✓",IF(D13>0,"⚠","↑"))),"") | F13: =IFERROR(SUMPRODUCT((T_Standards[מחלקה]=$A13)*(T_Standards[משמרת]="אמצע")*T_Standards[תקן]),0) -> 0 | G13: =IFERROR(COUNTIFS(T_Assign[תאריך],$B$3,T_Assign[משמרת],"אמצע",T_Assign[מחלקה],$A13),0) -> 0 | H13: =IFERROR(F13-G13,0) -> 0 | I13: =IFERROR(IF($A13="","",IF(H13=0,"✓",IF(H13>0,"⚠","↑"))),"") | J13: =IFERROR(SUMPRODUCT((T_Standards[מחלקה]=$A13)*(T_Standards[משמרת]="ערב")*T_Standards[תקן]),0) -> 0 | K13: =IFERROR(COUNTIFS(T_Assign[תאריך],$B$3,T_Assign[משמרת],"ערב",T_Assign[מחלקה],$A13),0) -> 0 | L13: =IFERROR(J13-K13,0) -> 0 | M13: =IFERROR(IF($A13="","",IF(L13=0,"✓",IF(L13>0,"⚠","↑"))),"") | N13: =IFERROR(SUM(B13,F13,J13),0) -> 0 | O13: =IFERROR(SUM(C13,G13,K13),0) -> 0 | P13: =IFERROR(N13-O13,0) -> 0 | Q13: =IFERROR(IF($A13="","",IF(P13=0,"✓ מאויש",IF(P13>0,"⚠ חוסר","↑ עודף"))),"")
A14: =IFERROR(INDEX(T_Depts[מחלקה],8),"") | B14: =IFERROR(SUMPRODUCT((T_Standards[מחלקה]=$A14)*(T_Standards[משמרת]="בוקר")*T_Standards[תקן]),0) -> 0 | C14: =IFERROR(COUNTIFS(T_Assign[תאריך],$B$3,T_Assign[משמרת],"בוקר",T_Assign[מחלקה],$A14),0) -> 0 | D14: =IFERROR(B14-C14,0) -> 0 | E14: =IFERROR(IF($A14="","",IF(D14=0,"✓",IF(D14>0,"⚠","↑"))),"") | F14: =IFERROR(SUMPRODUCT((T_Standards[מחלקה]=$A14)*(T_Standards[משמרת]="אמצע")*T_Standards[תקן]),0) -> 0 | G14: =IFERROR(COUNTIFS(T_Assign[תאריך],$B$3,T_Assign[משמרת],"אמצע",T_Assign[מחלקה],$A14),0) -> 0 | H14: =IFERROR(F14-G14,0) -> 0 | I14: =IFERROR(IF($A14="","",IF(H14=0,"✓",IF(H14>0,"⚠","↑"))),"") | J14: =IFERROR(SUMPRODUCT((T_Standards[מחלקה]=$A14)*(T_Standards[משמרת]="ערב")*T_Standards[תקן]),0) -> 0 | K14: =IFERROR(COUNTIFS(T_Assign[תאריך],$B$3,T_Assign[משמרת],"ערב",T_Assign[מחלקה],$A14),0) -> 0 | L14: =IFERROR(J14-K14,0) -> 0 | M14: =IFERROR(IF($A14="","",IF(L14=0,"✓",IF(L14>0,"⚠","↑"))),"") | N14: =IFERROR(SUM(B14,F14,J14),0) -> 0 | O14: =IFERROR(SUM(C14,G14,K14),0) -> 0 | P14: =IFERROR(N14-O14,0) -> 0 | Q14: =IFERROR(IF($A14="","",IF(P14=0,"✓ מאויש",IF(P14>0,"⚠ חוסר","↑ עודף"))),"")
A15: =IFERROR(INDEX(T_Depts[מחלקה],9),"") | B15: =IFERROR(SUMPRODUCT((T_Standards[מחלקה]=$A15)*(T_Standards[משמרת]="בוקר")*T_Standards[תקן]),0) -> 0 | C15: =IFERROR(COUNTIFS(T_Assign[תאריך],$B$3,T_Assign[משמרת],"בוקר",T_Assign[מחלקה],$A15),0) -> 0 | D15: =IFERROR(B15-C15,0) -> 0 | E15: =IFERROR(IF($A15="","",IF(D15=0,"✓",IF(D15>0,"⚠","↑"))),"") | F15: =IFERROR(SUMPRODUCT((T_Standards[מחלקה]=$A15)*(T_Standards[משמרת]="אמצע")*T_Standards[תקן]),0) -> 0 | G15: =IFERROR(COUNTIFS(T_Assign[תאריך],$B$3,T_Assign[משמרת],"אמצע",T_Assign[מחלקה],$A15),0) -> 0 | H15: =IFERROR(F15-G15,0) -> 0 | I15: =IFERROR(IF($A15="","",IF(H15=0,"✓",IF(H15>0,"⚠","↑"))),"") | J15: =IFERROR(SUMPRODUCT((T_Standards[מחלקה]=$A15)*(T_Standards[משמרת]="ערב")*T_Standards[תקן]),0) -> 0 | K15: =IFERROR(COUNTIFS(T_Assign[תאריך],$B$3,T_Assign[משמרת],"ערב",T_Assign[מחלקה],$A15),0) -> 0 | L15: =IFERROR(J15-K15,0) -> 0 | M15: =IFERROR(IF($A15="","",IF(L15=0,"✓",IF(L15>0,"⚠","↑"))),"") | N15: =IFERROR(SUM(B15,F15,J15),0) -> 0 | O15: =IFERROR(SUM(C15,G15,K15),0) -> 0 | P15: =IFERROR(N15-O15,0) -> 0 | Q15: =IFERROR(IF($A15="","",IF(P15=0,"✓ מאויש",IF(P15>0,"⚠ חוסר","↑ עודף"))),"")
A16: =IFERROR(INDEX(T_Depts[מחלקה],10),"") | B16: =IFERROR(SUMPRODUCT((T_Standards[מחלקה]=$A16)*(T_Standards[משמרת]="בוקר")*T_Standards[תקן]),0) -> 0 | C16: =IFERROR(COUNTIFS(T_Assign[תאריך],$B$3,T_Assign[משמרת],"בוקר",T_Assign[מחלקה],$A16),0) -> 0 | D16: =IFERROR(B16-C16,0) -> 0 | E16: =IFERROR(IF($A16="","",IF(D16=0,"✓",IF(D16>0,"⚠","↑"))),"") | F16: =IFERROR(SUMPRODUCT((T_Standards[מחלקה]=$A16)*(T_Standards[משמרת]="אמצע")*T_Standards[תקן]),0) -> 0 | G16: =IFERROR(COUNTIFS(T_Assign[תאריך],$B$3,T_Assign[משמרת],"אמצע",T_Assign[מחלקה],$A16),0) -> 0 | H16: =IFERROR(F16-G16,0) -> 0 | I16: =IFERROR(IF($A16="","",IF(H16=0,"✓",IF(H16>0,"⚠","↑"))),"") | J16: =IFERROR(SUMPRODUCT((T_Standards[מחלקה]=$A16)*(T_Standards[משמרת]="ערב")*T_Standards[תקן]),0) -> 0 | K16: =IFERROR(COUNTIFS(T_Assign[תאריך],$B$3,T_Assign[משמרת],"ערב",T_Assign[מחלקה],$A16),0) -> 0 | L16: =IFERROR(J16-K16,0) -> 0 | M16: =IFERROR(IF($A16="","",IF(L16=0,"✓",IF(L16>0,"⚠","↑"))),"") | N16: =IFERROR(SUM(B16,F16,J16),0) -> 0 | O16: =IFERROR(SUM(C16,G16,K16),0) -> 0 | P16: =IFERROR(N16-O16,0) -> 0 | Q16: =IFERROR(IF($A16="","",IF(P16=0,"✓ מאויש",IF(P16>0,"⚠ חוסר","↑ עודף"))),"")
A17: =IFERROR(INDEX(T_Depts[מחלקה],11),"") | B17: =IFERROR(SUMPRODUCT((T_Standards[מחלקה]=$A17)*(T_Standards[משמרת]="בוקר")*T_Standards[תקן]),0) -> 0 | C17: =IFERROR(COUNTIFS(T_Assign[תאריך],$B$3,T_Assign[משמרת],"בוקר",T_Assign[מחלקה],$A17),0) -> 0 | D17: =IFERROR(B17-C17,0) -> 0 | E17: =IFERROR(IF($A17="","",IF(D17=0,"✓",IF(D17>0,"⚠","↑"))),"") | F17: =IFERROR(SUMPRODUCT((T_Standards[מחלקה]=$A17)*(T_Standards[משמרת]="אמצע")*T_Standards[תקן]),0) -> 0 | G17: =IFERROR(COUNTIFS(T_Assign[תאריך],$B$3,T_Assign[משמרת],"אמצע",T_Assign[מחלקה],$A17),0) -> 0 | H17: =IFERROR(F17-G17,0) -> 0 | I17: =IFERROR(IF($A17="","",IF(H17=0,"✓",IF(H17>0,"⚠","↑"))),"") | J17: =IFERROR(SUMPRODUCT((T_Standards[מחלקה]=$A17)*(T_Standards[משמרת]="ערב")*T_Standards[תקן]),0) -> 0 | K17: =IFERROR(COUNTIFS(T_Assign[תאריך],$B$3,T_Assign[משמרת],"ערב",T_Assign[מחלקה],$A17),0) -> 0 | L17: =IFERROR(J17-K17,0) -> 0 | M17: =IFERROR(IF($A17="","",IF(L17=0,"✓",IF(L17>0,"⚠","↑"))),"") | N17: =IFERROR(SUM(B17,F17,J17),0) -> 0 | O17: =IFERROR(SUM(C17,G17,K17),0) -> 0 | P17: =IFERROR(N17-O17,0) -> 0 | Q17: =IFERROR(IF($A17="","",IF(P17=0,"✓ מאויש",IF(P17>0,"⚠ חוסר","↑ עודף"))),"")
A18: =IFERROR(INDEX(T_Depts[מחלקה],12),"") | B18: =IFERROR(SUMPRODUCT((T_Standards[מחלקה]=$A18)*(T_Standards[משמרת]="בוקר")*T_Standards[תקן]),0) -> 0 | C18: =IFERROR(COUNTIFS(T_Assign[תאריך],$B$3,T_Assign[משמרת],"בוקר",T_Assign[מחלקה],$A18),0) -> 0 | D18: =IFERROR(B18-C18,0) -> 0 | E18: =IFERROR(IF($A18="","",IF(D18=0,"✓",IF(D18>0,"⚠","↑"))),"") | F18: =IFERROR(SUMPRODUCT((T_Standards[מחלקה]=$A18)*(T_Standards[משמרת]="אמצע")*T_Standards[תקן]),0) -> 0 | G18: =IFERROR(COUNTIFS(T_Assign[תאריך],$B$3,T_Assign[משמרת],"אמצע",T_Assign[מחלקה],$A18),0) -> 0 | H18: =IFERROR(F18-G18,0) -> 0 | I18: =IFERROR(IF($A18="","",IF(H18=0,"✓",IF(H18>0,"⚠","↑"))),"") | J18: =IFERROR(SUMPRODUCT((T_Standards[מחלקה]=$A18)*(T_Standards[משמרת]="ערב")*T_Standards[תקן]),0) -> 0 | K18: =IFERROR(COUNTIFS(T_Assign[תאריך],$B$3,T_Assign[משמרת],"ערב",T_Assign[מחלקה],$A18),0) -> 0 | L18: =IFERROR(J18-K18,0) -> 0 | M18: =IFERROR(IF($A18="","",IF(L18=0,"✓",IF(L18>0,"⚠","↑"))),"") | N18: =IFERROR(SUM(B18,F18,J18),0) -> 0 | O18: =IFERROR(SUM(C18,G18,K18),0) -> 0 | P18: =IFERROR(N18-O18,0) -> 0 | Q18: =IFERROR(IF($A18="","",IF(P18=0,"✓ מאויש",IF(P18>0,"⚠ חוסר","↑ עודף"))),"")
A19: =IFERROR(INDEX(T_Depts[מחלקה],13),"") | B19: =IFERROR(SUMPRODUCT((T_Standards[מחלקה]=$A19)*(T_Standards[משמרת]="בוקר")*T_Standards[תקן]),0) -> 0 | C19: =IFERROR(COUNTIFS(T_Assign[תאריך],$B$3,T_Assign[משמרת],"בוקר",T_Assign[מחלקה],$A19),0) -> 0 | D19: =IFERROR(B19-C19,0) -> 0 | E19: =IFERROR(IF($A19="","",IF(D19=0,"✓",IF(D19>0,"⚠","↑"))),"") | F19: =IFERROR(SUMPRODUCT((T_Standards[מחלקה]=$A19)*(T_Standards[משמרת]="אמצע")*T_Standards[תקן]),0) -> 0 | G19: =IFERROR(COUNTIFS(T_Assign[תאריך],$B$3,T_Assign[משמרת],"אמצע",T_Assign[מחלקה],$A19),0) -> 0 | H19: =IFERROR(F19-G19,0) -> 0 | I19: =IFERROR(IF($A19="","",IF(H19=0,"✓",IF(H19>0,"⚠","↑"))),"") | J19: =IFERROR(SUMPRODUCT((T_Standards[מחלקה]=$A19)*(T_Standards[משמרת]="ערב")*T_Standards[תקן]),0) -> 0 | K19: =IFERROR(COUNTIFS(T_Assign[תאריך],$B$3,T_Assign[משמרת],"ערב",T_Assign[מחלקה],$A19),0) -> 0 | L19: =IFERROR(J19-K19,0) -> 0 | M19: =IFERROR(IF($A19="","",IF(L19=0,"✓",IF(L19>0,"⚠","↑"))),"") | N19: =IFERROR(SUM(B19,F19,J19),0) -> 0 | O19: =IFERROR(SUM(C19,G19,K19),0) -> 0 | P19: =IFERROR(N19-O19,0) -> 0 | Q19: =IFERROR(IF($A19="","",IF(P19=0,"✓ מאויש",IF(P19>0,"⚠ חוסר","↑ עודף"))),"")
A20: =IFERROR(INDEX(T_Depts[מחלקה],14),"") | B20: =IFERROR(SUMPRODUCT((T_Standards[מחלקה]=$A20)*(T_Standards[משמרת]="בוקר")*T_Standards[תקן]),0) -> 0 | C20: =IFERROR(COUNTIFS(T_Assign[תאריך],$B$3,T_Assign[משמרת],"בוקר",T_Assign[מחלקה],$A20),0) -> 0 | D20: =IFERROR(B20-C20,0) -> 0 | E20: =IFERROR(IF($A20="","",IF(D20=0,"✓",IF(D20>0,"⚠","↑"))),"") | F20: =IFERROR(SUMPRODUCT((T_Standards[מחלקה]=$A20)*(T_Standards[משמרת]="אמצע")*T_Standards[תקן]),0) -> 0 | G20: =IFERROR(COUNTIFS(T_Assign[תאריך],$B$3,T_Assign[משמרת],"אמצע",T_Assign[מחלקה],$A20),0) -> 0 | H20: =IFERROR(F20-G20,0) -> 0 | I20: =IFERROR(IF($A20="","",IF(H20=0,"✓",IF(H20>0,"⚠","↑"))),"") | J20: =IFERROR(SUMPRODUCT((T_Standards[מחלקה]=$A20)*(T_Standards[משמרת]="ערב")*T_Standards[תקן]),0) -> 0 | K20: =IFERROR(COUNTIFS(T_Assign[תאריך],$B$3,T_Assign[משמרת],"ערב",T_Assign[מחלקה],$A20),0) -> 0 | L20: =IFERROR(J20-K20,0) -> 0 | M20: =IFERROR(IF($A20="","",IF(L20=0,"✓",IF(L20>0,"⚠","↑"))),"") | N20: =IFERROR(SUM(B20,F20,J20),0) -> 0 | O20: =IFERROR(SUM(C20,G20,K20),0) -> 0 | P20: =IFERROR(N20-O20,0) -> 0 | Q20: =IFERROR(IF($A20="","",IF(P20=0,"✓ מאויש",IF(P20>0,"⚠ חוסר","↑ עודף"))),"")
A21: =IFERROR(INDEX(T_Depts[מחלקה],15),"") | B21: =IFERROR(SUMPRODUCT((T_Standards[מחלקה]=$A21)*(T_Standards[משמרת]="בוקר")*T_Standards[תקן]),0) -> 0 | C21: =IFERROR(COUNTIFS(T_Assign[תאריך],$B$3,T_Assign[משמרת],"בוקר",T_Assign[מחלקה],$A21),0) -> 0 | D21: =IFERROR(B21-C21,0) -> 0 | E21: =IFERROR(IF($A21="","",IF(D21=0,"✓",IF(D21>0,"⚠","↑"))),"") | F21: =IFERROR(SUMPRODUCT((T_Standards[מחלקה]=$A21)*(T_Standards[משמרת]="אמצע")*T_Standards[תקן]),0) -> 0 | G21: =IFERROR(COUNTIFS(T_Assign[תאריך],$B$3,T_Assign[משמרת],"אמצע",T_Assign[מחלקה],$A21),0) -> 0 | H21: =IFERROR(F21-G21,0) -> 0 | I21: =IFERROR(IF($A21="","",IF(H21=0,"✓",IF(H21>0,"⚠","↑"))),"") | J21: =IFERROR(SUMPRODUCT((T_Standards[מחלקה]=$A21)*(T_Standards[משמרת]="ערב")*T_Standards[תקן]),0) -> 0 | K21: =IFERROR(COUNTIFS(T_Assign[תאריך],$B$3,T_Assign[משמרת],"ערב",T_Assign[מחלקה],$A21),0) -> 0 | L21: =IFERROR(J21-K21,0) -> 0 | M21: =IFERROR(IF($A21="","",IF(L21=0,"✓",IF(L21>0,"⚠","↑"))),"") | N21: =IFERROR(SUM(B21,F21,J21),0) -> 0 | O21: =IFERROR(SUM(C21,G21,K21),0) -> 0 | P21: =IFERROR(N21-O21,0) -> 0 | Q21: =IFERROR(IF($A21="","",IF(P21=0,"✓ מאויש",IF(P21>0,"⚠ חוסר","↑ עודף"))),"")
A22: סה״כ | B22: =IFERROR(SUM(B7:B21),0) -> 0 | C22: =IFERROR(SUM(C7:C21),0) -> 0 | D22: =IFERROR(SUM(D7:D21),0) -> 0 | F22: =IFERROR(SUM(F7:F21),0) -> 0 | G22: =IFERROR(SUM(G7:G21),0) -> 0 | H22: =IFERROR(SUM(H7:H21),0) -> 0 | J22: =IFERROR(SUM(J7:J21),0) -> 0 | K22: =IFERROR(SUM(K7:K21),0) -> 0 | L22: =IFERROR(SUM(L7:L21),0) -> 0 | N22: =IFERROR(SUM(N7:N21),0) -> 0 | O22: =IFERROR(SUM(O7:O21),0) -> 0 | P22: =IFERROR(SUM(P7:P21),0) -> 0

Sheet לוח_שבועי_כללי
A1: 📆 לוח משמרות שבועי — כל המחלקות יחד
A3: שבוע: | B3: =הגדרות!$C$3 -> 46096 | C3: עד: | D3: =הגדרות!$C$3+6 -> 46102
A5: מחלקה | B5: א׳ | F5: ב׳ | J5: ג׳ | N5: ד׳ | R5: ה׳ | V5: ו׳ | Z5: ש׳ | AD5: סה״כ שבועי
B6: =הגדרות!$C$3+0 -> 46096 | F6: =הגדרות!$C$3+1 -> 46097 | J6: =הגדרות!$C$3+2 -> 46098 | N6: =הגדרות!$C$3+3 -> 46099 | R6: =הגדרות!$C$3+4 -> 46100 | V6: =הגדרות!$C$3+5 -> 46101 | Z6: =הגדרות!$C$3+6 -> 46102
B7: בוקר | C7: אמצע | D7: ערב | E7: סה״כ | F7: בוקר | G7: אמצע | H7: ערב | I7: סה״כ | J7: בוקר | K7: אמצע | L7: ערב | M7: סה״כ | N7: בוקר | O7: אמצע | P7: ערב | Q7: סה״כ | R7: בוקר | S7: אמצע | T7: ערב | U7: סה״כ | V7: בוקר | W7: אמצע | X7: ערב | Y7: סה״כ | Z7: בוקר | AA7: אמצע | AB7: ערב | AC7: סה״כ | AD7: שובצו | AE7: תקן | AF7: פער
A8: =IFERROR(INDEX(T_Depts[מחלקה],1),"") | B8: =IFERROR(COUNTIFS(T_Assign[תאריך],B6,T_Assign[משמרת],"בוקר",T_Assign[מחלקה],$A8),0) -> 0 | C8: =IFERROR(COUNTIFS(T_Assign[תאריך],B6,T_Assign[משמרת],"אמצע",T_Assign[מחלקה],$A8),0) -> 0 | D8: =IFERROR(COUNTIFS(T_Assign[תאריך],B6,T_Assign[משמרת],"ערב",T_Assign[מחלקה],$A8),0) -> 0 | E8: =IFERROR(SUM(B8:D8),0) -> 0 | F8: =IFERROR(COUNTIFS(T_Assign[תאריך],F6,T_Assign[משמרת],"בוקר",T_Assign[מחלקה],$A8),0) -> 0 | G8: =IFERROR(COUNTIFS(T_Assign[תאריך],F6,T_Assign[משמרת],"אמצע",T_Assign[מחלקה],$A8),0) -> 0 | H8: =IFERROR(COUNTIFS(T_Assign[תאריך],F6,T_Assign[משמרת],"ערב",T_Assign[מחלקה],$A8),0) -> 0 | I8: =IFERROR(SUM(F8:H8),0) -> 0 | J8: =IFERROR(COUNTIFS(T_Assign[תאריך],J6,T_Assign[משמרת],"בוקר",T_Assign[מחלקה],$A8),0) -> 0 | K8: =IFERROR(COUNTIFS(T_Assign[תאריך],J6,T_Assign[משמרת],"אמצע",T_Assign[מחלקה],$A8),0) -> 0 | L8: =IFERROR(COUNTIFS(T_Assign[תאריך],J6,T_Assign[משמרת],"ערב",T_Assign[מחלקה],$A8),0) -> 0 | M8: =IFERROR(SUM(J8:L8),0) -> 0 | N8: =IFERROR(COUNTIFS(T_Assign[תאריך],N6,T_Assign[משמרת],"בוקר",T_Assign[מחלקה],$A8),0) -> 0 | O8: =IFERROR(COUNTIFS(T_Assign[תאריך],N6,T_Assign[משמרת],"אמצע",T_Assign[מחלקה],$A8),0) -> 0 | P8: =IFERROR(COUNTIFS(T_Assign[תאריך],N6,T_Assign[משמרת],"ערב",T_Assign[מחלקה],$A8),0) -> 0 | Q8: =IFERROR(SUM(N8:P8),0) -> 0 | R8: =IFERROR(COUNTIFS(T_Assign[תאריך],R6,T_Assign[משמרת],"בוקר",T_Assign[מחלקה],$A8),0) -> 0 | S8: =IFERROR(COUNTIFS(T_Assign[תאריך],R6,T_Assign[משמרת],"אמצע",T_Assign[מחלקה],$A8),0) -> 0 | T8: =IFERROR(COUNTIFS(T_Assign[תאריך],R6,T_Assign[משמרת],"ערב",T_Assign[מחלקה],$A8),0) -> 0 | U8: =IFERROR(SUM(R8:T8),0) -> 0 | V8: =IFERROR(COUNTIFS(T_Assign[תאריך],V6,T_Assign[משמרת],"בוקר",T_Assign[מחלקה],$A8),0) -> 0 | W8: =IFERROR(COUNTIFS(T_Assign[תאריך],V6,T_Assign[משמרת],"אמצע",T_Assign[מחלקה],$A8),0) -> 0 | X8: =IFERROR(COUNTIFS(T_Assign[תאריך],V6,T_Assign[משמרת],"ערב",T_Assign[מחלקה],$A8),0) -> 0 | Y8: =IFERROR(SUM(V8:X8),0) -> 0 | Z8: =IFERROR(COUNTIFS(T_Assign[תאריך],Z6,T_Assign[משמרת],"בוקר",T_Assign[מחלקה],$A8),0) -> 0 | AA8: =IFERROR(COUNTIFS(T_Assign[תאריך],Z6,T_Assign[משמרת],"אמצע",T_Assign[מחלקה],$A8),0) -> 0 | AB8: =IFERROR(COUNTIFS(T_Assign[תאריך],Z6,T_Assign[משמרת],"ערב",T_Assign[מחלקה],$A8),0) -> 0 | AC8: =IFERROR(SUM(Z8:AB8),0) -> 0 | AD8: =IFERROR(E8+I8+M8+Q8+U8+Y8+AC8,0) -> 0 | AE8: =IFERROR(SUMPRODUCT((T_Standards[מחלקה]=$A8)*T_Standards[תקן])*7,0) -> 0 | AF8: =IFERROR(AE8-AD8,0) -> 0
A9: =IFERROR(INDEX(T_Depts[מחלקה],2),"") | B9: =IFERROR(COUNTIFS(T_Assign[תאריך],B6,T_Assign[משמרת],"בוקר",T_Assign[מחלקה],$A9),0) -> 0 | C9: =IFERROR(COUNTIFS(T_Assign[תאריך],B6,T_Assign[משמרת],"אמצע",T_Assign[מחלקה],$A9),0) -> 0 | D9: =IFERROR(COUNTIFS(T_Assign[תאריך],B6,T_Assign[משמרת],"ערב",T_Assign[מחלקה],$A9),0) -> 0 | E9: =IFERROR(SUM(B9:D9),0) -> 0 | F9: =IFERROR(COUNTIFS(T_Assign[תאריך],F6,T_Assign[משמרת],"בוקר",T_Assign[מחלקה],$A9),0) -> 0 | G9: =IFERROR(COUNTIFS(T_Assign[תאריך],F6,T_Assign[משמרת],"אמצע",T_Assign[מחלקה],$A9),0) -> 0 | H9: =IFERROR(COUNTIFS(T_Assign[תאריך],F6,T_Assign[משמרת],"ערב",T_Assign[מחלקה],$A9),0) -> 0 | I9: =IFERROR(SUM(F9:H9),0) -> 0 | J9: =IFERROR(COUNTIFS(T_Assign[תאריך],J6,T_Assign[משמרת],"בוקר",T_Assign[מחלקה],$A9),0) -> 0 | K9: =IFERROR(COUNTIFS(T_Assign[תאריך],J6,T_Assign[משמרת],"אמצע",T_Assign[מחלקה],$A9),0) -> 0 | L9: =IFERROR(COUNTIFS(T_Assign[תאריך],J6,T_Assign[משמרת],"ערב",T_Assign[מחלקה],$A9),0) -> 0 | M9: =IFERROR(SUM(J9:L9),0) -> 0 | N9: =IFERROR(COUNTIFS(T_Assign[תאריך],N6,T_Assign[משמרת],"בוקר",T_Assign[מחלקה],$A9),0) -> 0 | O9: =IFERROR(COUNTIFS(T_Assign[תאריך],N6,T_Assign[משמרת],"אמצע",T_Assign[מחלקה],$A9),0) -> 0 | P9: =IFERROR(COUNTIFS(T_Assign[תאריך],N6,T_Assign[משמרת],"ערב",T_Assign[מחלקה],$A9),0) -> 0 | Q9: =IFERROR(SUM(N9:P9),0) -> 0 | R9: =IFERROR(COUNTIFS(T_Assign[תאריך],R6,T_Assign[משמרת],"בוקר",T_Assign[מחלקה],$A9),0) -> 0 | S9: =IFERROR(COUNTIFS(T_Assign[תאריך],R6,T_Assign[משמרת],"אמצע",T_Assign[מחלקה],$A9),0) -> 0 | T9: =IFERROR(COUNTIFS(T_Assign[תאריך],R6,T_Assign[משמרת],"ערב",T_Assign[מחלקה],$A9),0) -> 0 | U9: =IFERROR(SUM(R9:T9),0) -> 0 | V9: =IFERROR(COUNTIFS(T_Assign[תאריך],V6,T_Assign[משמרת],"בוקר",T_Assign[מחלקה],$A9),0) -> 0 | W9: =IFERROR(COUNTIFS(T_Assign[תאריך],V6,T_Assign[משמרת],"אמצע",T_Assign[מחלקה],$A9),0) -> 0 | X9: =IFERROR(COUNTIFS(T_Assign[תאריך],V6,T_Assign[משמרת],"ערב",T_Assign[מחלקה],$A9),0) -> 0 | Y9: =IFERROR(SUM(V9:X9),0) -> 0 | Z9: =IFERROR(COUNTIFS(T_Assign[תאריך],Z6,T_Assign[משמרת],"בוקר",T_Assign[מחלקה],$A9),0) -> 0 | AA9: =IFERROR(COUNTIFS(T_Assign[תאריך],Z6,T_Assign[משמרת],"אמצע",T_Assign[מחלקה],$A9),0) -> 0 | AB9: =IFERROR(COUNTIFS(T_Assign[תאריך],Z6,T_Assign[משמרת],"ערב",T_Assign[מחלקה],$A9),0) -> 0 | AC9: =IFERROR(SUM(Z9:AB9),0) -> 0 | AD9: =IFERROR(E9+I9+M9+Q9+U9+Y9+AC9,0) -> 0 | AE9: =IFERROR(SUMPRODUCT((T_Standards[מחלקה]=$A9)*T_Standards[תקן])*7,0) -> 0 | AF9: =IFERROR(AE9-AD9,0) -> 0
A10: =IFERROR(INDEX(T_Depts[מחלקה],3),"") | B10: =IFERROR(COUNTIFS(T_Assign[תאריך],B6,T_Assign[משמרת],"בוקר",T_Assign[מחלקה],$A10),0) -> 0 | C10: =IFERROR(COUNTIFS(T_Assign[תאריך],B6,T_Assign[משמרת],"אמצע",T_Assign[מחלקה],$A10),0) -> 0 | D10: =IFERROR(COUNTIFS(T_Assign[תאריך],B6,T_Assign[משמרת],"ערב",T_Assign[מחלקה],$A10),0) -> 0 | E10: =IFERROR(SUM(B10:D10),0) -> 0 | F10: =IFERROR(COUNTIFS(T_Assign[תאריך],F6,T_Assign[משמרת],"בוקר",T_Assign[מחלקה],$A10),0) -> 0 | G10: =IFERROR(COUNTIFS(T_Assign[תאריך],F6,T_Assign[משמרת],"אמצע",T_Assign[מחלקה],$A10),0) -> 0 | H10: =IFERROR(COUNTIFS(T_Assign[תאריך],F6,T_Assign[משמרת],"ערב",T_Assign[מחלקה],$A10),0) -> 0 | I10: =IFERROR(SUM(F10:H10),0) -> 0 | J10: =IFERROR(COUNTIFS(T_Assign[תאריך],J6,T_Assign[משמרת],"בוקר",T_Assign[מחלקה],$A10),0) -> 0 | K10: =IFERROR(COUNTIFS(T_Assign[תאריך],J6,T_Assign[משמרת],"אמצע",T_Assign[מחלקה],$A10),0) -> 0 | L10: =IFERROR(COUNTIFS(T_Assign[תאריך],J6,T_Assign[משמרת],"ערב",T_Assign[מחלקה],$A10),0) -> 0 | M10: =IFERROR(SUM(J10:L10),0) -> 0 | N10: =IFERROR(COUNTIFS(T_Assign[תאריך],N6,T_Assign[משמרת],"בוקר",T_Assign[מחלקה],$A10),0) -> 0 | O10: =IFERROR(COUNTIFS(T_Assign[תאריך],N6,T_Assign[משמרת],"אמצע",T_Assign[מחלקה],$A10),0) -> 0 | P10: =IFERROR(COUNTIFS(T_Assign[תאריך],N6,T_Assign[משמרת],"ערב",T_Assign[מחלקה],$A10),0) -> 0 | Q10: =IFERROR(SUM(N10:P10),0) -> 0 | R10: =IFERROR(COUNTIFS(T_Assign[תאריך],R6,T_Assign[משמרת],"בוקר",T_Assign[מחלקה],$A10),0) -> 0 | S10: =IFERROR(COUNTIFS(T_Assign[תאריך],R6,T_Assign[משמרת],"אמצע",T_Assign[מחלקה],$A10),0) -> 0 | T10: =IFERROR(COUNTIFS(T_Assign[תאריך],R6,T_Assign[משמרת],"ערב",T_Assign[מחלקה],$A10),0) -> 0 | U10: =IFERROR(SUM(R10:T10),0) -> 0 | V10: =IFERROR(COUNTIFS(T_Assign[תאריך],V6,T_Assign[משמרת],"בוקר",T_Assign[מחלקה],$A10),0) -> 0 | W10: =IFERROR(COUNTIFS(T_Assign[תאריך],V6,T_Assign[משמרת],"אמצע",T_Assign[מחלקה],$A10),0) -> 0 | X10: =IFERROR(COUNTIFS(T_Assign[תאריך],V6,T_Assign[משמרת],"ערב",T_Assign[מחלקה],$A10),0) -> 0 | Y10: =IFERROR(SUM(V10:X10),0) -> 0 | Z10: =IFERROR(COUNTIFS(T_Assign[תאריך],Z6,T_Assign[משמרת],"בוקר",T_Assign[מחלקה],$A10),0) -> 0 | AA10: =IFERROR(COUNTIFS(T_Assign[תאריך],Z6,T_Assign[משמרת],"אמצע",T_Assign[מחלקה],$A10),0) -> 0 | AB10: =IFERROR(COUNTIFS(T_Assign[תאריך],Z6,T_Assign[משמרת],"ערב",T_Assign[מחלקה],$A10),0) -> 0 | AC10: =IFERROR(SUM(Z10:AB10),0) -> 0 | AD10: =IFERROR(E10+I10+M10+Q10+U10+Y10+AC10,0) -> 0 | AE10: =IFERROR(SUMPRODUCT((T_Standards[מחלקה]=$A10)*T_Standards[תקן])*7,0) -> 0 | AF10: =IFERROR(AE10-AD10,0) -> 0
A11: =IFERROR(INDEX(T_Depts[מחלקה],4),"") | B11: =IFERROR(COUNTIFS(T_Assign[תאריך],B6,T_Assign[משמרת],"בוקר",T_Assign[מחלקה],$A11),0) -> 0 | C11: =IFERROR(COUNTIFS(T_Assign[תאריך],B6,T_Assign[משמרת],"אמצע",T_Assign[מחלקה],$A11),0) -> 0 | D11: =IFERROR(COUNTIFS(T_Assign[תאריך],B6,T_Assign[משמרת],"ערב",T_Assign[מחלקה],$A11),0) -> 0 | E11: =IFERROR(SUM(B11:D11),0) -> 0 | F11: =IFERROR(COUNTIFS(T_Assign[תאריך],F6,T_Assign[משמרת],"בוקר",T_Assign[מחלקה],$A11),0) -> 0 | G11: =IFERROR(COUNTIFS(T_Assign[תאריך],F6,T_Assign[משמרת],"אמצע",T_Assign[מחלקה],$A11),0) -> 0 | H11: =IFERROR(COUNTIFS(T_Assign[תאריך],F6,T_Assign[משמרת],"ערב",T_Assign[מחלקה],$A11),0) -> 0 | I11: =IFERROR(SUM(F11:H11),0) -> 0 | J11: =IFERROR(COUNTIFS(T_Assign[תאריך],J6,T_Assign[משמרת],"בוקר",T_Assign[מחלקה],$A11),0) -> 0 | K11: =IFERROR(COUNTIFS(T_Assign[תאריך],J6,T_Assign[משמרת],"אמצע",T_Assign[מחלקה],$A11),0) -> 0 | L11: =IFERROR(COUNTIFS(T_Assign[תאריך],J6,T_Assign[משמרת],"ערב",T_Assign[מחלקה],$A11),0) -> 0 | M11: =IFERROR(SUM(J11:L11),0) -> 0 | N11: =IFERROR(COUNTIFS(T_Assign[תאריך],N6,T_Assign[משמרת],"בוקר",T_Assign[מחלקה],$A11),0) -> 0 | O11: =IFERROR(COUNTIFS(T_Assign[תאריך],N6,T_Assign[משמרת],"אמצע",T_Assign[מחלקה],$A11),0) -> 0 | P11: =IFERROR(COUNTIFS(T_Assign[תאריך],N6,T_Assign[משמרת],"ערב",T_Assign[מחלקה],$A11),0) -> 0 | Q11: =IFERROR(SUM(N11:P11),0) -> 0 | R11: =IFERROR(COUNTIFS(T_Assign[תאריך],R6,T_Assign[משמרת],"בוקר",T_Assign[מחלקה],$A11),0) -> 0 | S11: =IFERROR(COUNTIFS(T_Assign[תאריך],R6,T_Assign[משמרת],"אמצע",T_Assign[מחלקה],$A11),0) -> 0 | T11: =IFERROR(COUNTIFS(T_Assign[תאריך],R6,T_Assign[משמרת],"ערב",T_Assign[מחלקה],$A11),0) -> 0 | U11: =IFERROR(SUM(R11:T11),0) -> 0 | V11: =IFERROR(COUNTIFS(T_Assign[תאריך],V6,T_Assign[משמרת],"בוקר",T_Assign[מחלקה],$A11),0) -> 0 | W11: =IFERROR(COUNTIFS(T_Assign[תאריך],V6,T_Assign[משמרת],"אמצע",T_Assign[מחלקה],$A11),0) -> 0 | X11: =IFERROR(COUNTIFS(T_Assign[תאריך],V6,T_Assign[משמרת],"ערב",T_Assign[מחלקה],$A11),0) -> 0 | Y11: =IFERROR(SUM(V11:X11),0) -> 0 | Z11: =IFERROR(COUNTIFS(T_Assign[תאריך],Z6,T_Assign[משמרת],"בוקר",T_Assign[מחלקה],$A11),0) -> 0 | AA11: =IFERROR(COUNTIFS(T_Assign[תאריך],Z6,T_Assign[משמרת],"אמצע",T_Assign[מחלקה],$A11),0) -> 0 | AB11: =IFERROR(COUNTIFS(T_Assign[תאריך],Z6,T_Assign[משמרת],"ערב",T_Assign[מחלקה],$A11),0) -> 0 | AC11: =IFERROR(SUM(Z11:AB11),0) -> 0 | AD11: =IFERROR(E11+I11+M11+Q11+U11+Y11+AC11,0) -> 0 | AE11: =IFERROR(SUMPRODUCT((T_Standards[מחלקה]=$A11)*T_Standards[תקן])*7,0) -> 0 | AF11: =IFERROR(AE11-AD11,0) -> 0
A12: =IFERROR(INDEX(T_Depts[מחלקה],5),"") | B12: =IFERROR(COUNTIFS(T_Assign[תאריך],B6,T_Assign[משמרת],"בוקר",T_Assign[מחלקה],$A12),0) -> 0 | C12: =IFERROR(COUNTIFS(T_Assign[תאריך],B6,T_Assign[משמרת],"אמצע",T_Assign[מחלקה],$A12),0) -> 0 | D12: =IFERROR(COUNTIFS(T_Assign[תאריך],B6,T_Assign[משמרת],"ערב",T_Assign[מחלקה],$A12),0) -> 0 | E12: =IFERROR(SUM(B12:D12),0) -> 0 | F12: =IFERROR(COUNTIFS(T_Assign[תאריך],F6,T_Assign[משמרת],"בוקר",T_Assign[מחלקה],$A12),0) -> 0 | G12: =IFERROR(COUNTIFS(T_Assign[תאריך],F6,T_Assign[משמרת],"אמצע",T_Assign[מחלקה],$A12),0) -> 0 | H12: =IFERROR(COUNTIFS(T_Assign[תאריך],F6,T_Assign[משמרת],"ערב",T_Assign[מחלקה],$A12),0) -> 0 | I12: =IFERROR(SUM(F12:H12),0) -> 0 | J12: =IFERROR(COUNTIFS(T_Assign[תאריך],J6,T_Assign[משמרת],"בוקר",T_Assign[מחלקה],$A12),0) -> 0 | K12: =IFERROR(COUNTIFS(T_Assign[תאריך],J6,T_Assign[משמרת],"אמצע",T_Assign[מחלקה],$A12),0) -> 0 | L12: =IFERROR(COUNTIFS(T_Assign[תאריך],J6,T_Assign[משמרת],"ערב",T_Assign[מחלקה],$A12),0) -> 0 | M12: =IFERROR(SUM(J12:L12),0) -> 0 | N12: =IFERROR(COUNTIFS(T_Assign[תאריך],N6,T_Assign[משמרת],"בוקר",T_Assign[מחלקה],$A12),0) -> 0 | O12: =IFERROR(COUNTIFS(T_Assign[תאריך],N6,T_Assign[משמרת],"אמצע",T_Assign[מחלקה],$A12),0) -> 0 | P12: =IFERROR(COUNTIFS(T_Assign[תאריך],N6,T_Assign[משמרת],"ערב",T_Assign[מחלקה],$A12),0) -> 0 | Q12: =IFERROR(SUM(N12:P12),0) -> 0 | R12: =IFERROR(COUNTIFS(T_Assign[תאריך],R6,T_Assign[משמרת],"בוקר",T_Assign[מחלקה],$A12),0) -> 0 | S12: =IFERROR(COUNTIFS(T_Assign[תאריך],R6,T_Assign[משמרת],"אמצע",T_Assign[מחלקה],$A12),0) -> 0 | T12: =IFERROR(COUNTIFS(T_Assign[תאריך],R6,T_Assign[משמרת],"ערב",T_Assign[מחלקה],$A12),0) -> 0 | U12: =IFERROR(SUM(R12:T12),0) -> 0 | V12: =IFERROR(COUNTIFS(T_Assign[תאריך],V6,T_Assign[משמרת],"בוקר",T_Assign[מחלקה],$A12),0) -> 0 | W12: =IFERROR(COUNTIFS(T_Assign[תאריך],V6,T_Assign[משמרת],"אמצע",T_Assign[מחלקה],$A12),0) -> 0 | X12: =IFERROR(COUNTIFS(T_Assign[תאריך],V6,T_Assign[משמרת],"ערב",T_Assign[מחלקה],$A12),0) -> 0 | Y12: =IFERROR(SUM(V12:X12),0) -> 0 | Z12: =IFERROR(COUNTIFS(T_Assign[תאריך],Z6,T_Assign[משמרת],"בוקר",T_Assign[מחלקה],$A12),0) -> 0 | AA12: =IFERROR(COUNTIFS(T_Assign[תאריך],Z6,T_Assign[משמרת],"אמצע",T_Assign[מחלקה],$A12),0) -> 0 | AB12: =IFERROR(COUNTIFS(T_Assign[תאריך],Z6,T_Assign[משמרת],"ערב",T_Assign[מחלקה],$A12),0) -> 0 | AC12: =IFERROR(SUM(Z12:AB12),0) -> 0 | AD12: =IFERROR(E12+I12+M12+Q12+U12+Y12+AC12,0) -> 0 | AE12: =IFERROR(SUMPRODUCT((T_Standards[מחלקה]=$A12)*T_Standards[תקן])*7,0) -> 0 | AF12: =IFERROR(AE12-AD12,0) -> 0
A13: =IFERROR(INDEX(T_Depts[מחלקה],6),"") | B13: =IFERROR(COUNTIFS(T_Assign[תאריך],B6,T_Assign[משמרת],"בוקר",T_Assign[מחלקה],$A13),0) -> 0 | C13: =IFERROR(COUNTIFS(T_Assign[תאריך],B6,T_Assign[משמרת],"אמצע",T_Assign[מחלקה],$A13),0) -> 0 | D13: =IFERROR(COUNTIFS(T_Assign[תאריך],B6,T_Assign[משמרת],"ערב",T_Assign[מחלקה],$A13),0) -> 0 | E13: =IFERROR(SUM(B13:D13),0) -> 0 | F13: =IFERROR(COUNTIFS(T_Assign[תאריך],F6,T_Assign[משמרת],"בוקר",T_Assign[מחלקה],$A13),0) -> 0 | G13: =IFERROR(COUNTIFS(T_Assign[תאריך],F6,T_Assign[משמרת],"אמצע",T_Assign[מחלקה],$A13),0) -> 0 | H13: =IFERROR(COUNTIFS(T_Assign[תאריך],F6,T_Assign[משמרת],"ערב",T_Assign[מחלקה],$A13),0) -> 0 | I13: =IFERROR(SUM(F13:H13),0) -> 0 | J13: =IFERROR(COUNTIFS(T_Assign[תאריך],J6,T_Assign[משמרת],"בוקר",T_Assign[מחלקה],$A13),0) -> 0 | K13: =IFERROR(COUNTIFS(T_Assign[תאריך],J6,T_Assign[משמרת],"אמצע",T_Assign[מחלקה],$A13),0) -> 0 | L13: =IFERROR(COUNTIFS(T_Assign[תאריך],J6,T_Assign[משמרת],"ערב",T_Assign[מחלקה],$A13),0) -> 0 | M13: =IFERROR(SUM(J13:L13),0) -> 0 | N13: =IFERROR(COUNTIFS(T_Assign[תאריך],N6,T_Assign[משמרת],"בוקר",T_Assign[מחלקה],$A13),0) -> 0 | O13: =IFERROR(COUNTIFS(T_Assign[תאריך],N6,T_Assign[משמרת],"אמצע",T_Assign[מחלקה],$A13),0) -> 0 | P13: =IFERROR(COUNTIFS(T_Assign[תאריך],N6,T_Assign[משמרת],"ערב",T_Assign[מחלקה],$A13),0) -> 0 | Q13: =IFERROR(SUM(N13:P13),0) -> 0 | R13: =IFERROR(COUNTIFS(T_Assign[תאריך],R6,T_Assign[משמרת],"בוקר",T_Assign[מחלקה],$A13),0) -> 0 | S13: =IFERROR(COUNTIFS(T_Assign[תאריך],R6,T_Assign[משמרת],"אמצע",T_Assign[מחלקה],$A13),0) -> 0 | T13: =IFERROR(COUNTIFS(T_Assign[תאריך],R6,T_Assign[משמרת],"ערב",T_Assign[מחלקה],$A13),0) -> 0 | U13: =IFERROR(SUM(R13:T13),0) -> 0 | V13: =IFERROR(COUNTIFS(T_Assign[תאריך],V6,T_Assign[משמרת],"בוקר",T_Assign[מחלקה],$A13),0) -> 0 | W13: =IFERROR(COUNTIFS(T_Assign[תאריך],V6,T_Assign[משמרת],"אמצע",T_Assign[מחלקה],$A13),0) -> 0 | X13: =IFERROR(COUNTIFS(T_Assign[תאריך],V6,T_Assign[משמרת],"ערב",T_Assign[מחלקה],$A13),0) -> 0 | Y13: =IFERROR(SUM(V13:X13),0) -> 0 | Z13: =IFERROR(COUNTIFS(T_Assign[תאריך],Z6,T_Assign[משמרת],"בוקר",T_Assign[מחלקה],$A13),0) -> 0 | AA13: =IFERROR(COUNTIFS(T_Assign[תאריך],Z6,T_Assign[משמרת],"אמצע",T_Assign[מחלקה],$A13),0) -> 0 | AB13: =IFERROR(COUNTIFS(T_Assign[תאריך],Z6,T_Assign[משמרת],"ערב",T_Assign[מחלקה],$A13),0) -> 0 | AC13: =IFERROR(SUM(Z13:AB13),0) -> 0 | AD13: =IFERROR(E13+I13+M13+Q13+U13+Y13+AC13,0) -> 0 | AE13: =IFERROR(SUMPRODUCT((T_Standards[מחלקה]=$A13)*T_Standards[תקן])*7,0) -> 0 | AF13: =IFERROR(AE13-AD13,0) -> 0
A14: =IFERROR(INDEX(T_Depts[מחלקה],7),"") | B14: =IFERROR(COUNTIFS(T_Assign[תאריך],B6,T_Assign[משמרת],"בוקר",T_Assign[מחלקה],$A14),0) -> 0 | C14: =IFERROR(COUNTIFS(T_Assign[תאריך],B6,T_Assign[משמרת],"אמצע",T_Assign[מחלקה],$A14),0) -> 0 | D14: =IFERROR(COUNTIFS(T_Assign[תאריך],B6,T_Assign[משמרת],"ערב",T_Assign[מחלקה],$A14),0) -> 0 | E14: =IFERROR(SUM(B14:D14),0) -> 0 | F14: =IFERROR(COUNTIFS(T_Assign[תאריך],F6,T_Assign[משמרת],"בוקר",T_Assign[מחלקה],$A14),0) -> 0 | G14: =IFERROR(COUNTIFS(T_Assign[תאריך],F6,T_Assign[משמרת],"אמצע",T_Assign[מחלקה],$A14),0) -> 0 | H14: =IFERROR(COUNTIFS(T_Assign[תאריך],F6,T_Assign[משמרת],"ערב",T_Assign[מחלקה],$A14),0) -> 0 | I14: =IFERROR(SUM(F14:H14),0) -> 0 | J14: =IFERROR(COUNTIFS(T_Assign[תאריך],J6,T_Assign[משמרת],"בוקר",T_Assign[מחלקה],$A14),0) -> 0 | K14: =IFERROR(COUNTIFS(T_Assign[תאריך],J6,T_Assign[משמרת],"אמצע",T_Assign[מחלקה],$A14),0) -> 0 | L14: =IFERROR(COUNTIFS(T_Assign[תאריך],J6,T_Assign[משמרת],"ערב",T_Assign[מחלקה],$A14),0) -> 0 | M14: =IFERROR(SUM(J14:L14),0) -> 0 | N14: =IFERROR(COUNTIFS(T_Assign[תאריך],N6,T_Assign[משמרת],"בוקר",T_Assign[מחלקה],$A14),0) -> 0 | O14: =IFERROR(COUNTIFS(T_Assign[תאריך],N6,T_Assign[משמרת],"אמצע",T_Assign[מחלקה],$A14),0) -> 0 | P14: =IFERROR(COUNTIFS(T_Assign[תאריך],N6,T_Assign[משמרת],"ערב",T_Assign[מחלקה],$A14),0) -> 0 | Q14: =IFERROR(SUM(N14:P14),0) -> 0 | R14: =IFERROR(COUNTIFS(T_Assign[תאריך],R6,T_Assign[משמרת],"בוקר",T_Assign[מחלקה],$A14),0) -> 0 | S14: =IFERROR(COUNTIFS(T_Assign[תאריך],R6,T_Assign[משמרת],"אמצע",T_Assign[מחלקה],$A14),0) -> 0 | T14: =IFERROR(COUNTIFS(T_Assign[תאריך],R6,T_Assign[משמרת],"ערב",T_Assign[מחלקה],$A14),0) -> 0 | U14: =IFERROR(SUM(R14:T14),0) -> 0 | V14: =IFERROR(COUNTIFS(T_Assign[תאריך],V6,T_Assign[משמרת],"בוקר",T_Assign[מחלקה],$A14),0) -> 0 | W14: =IFERROR(COUNTIFS(T_Assign[תאריך],V6,T_Assign[משמרת],"אמצע",T_Assign[מחלקה],$A14),0) -> 0 | X14: =IFERROR(COUNTIFS(T_Assign[תאריך],V6,T_Assign[משמרת],"ערב",T_Assign[מחלקה],$A14),0) -> 0 | Y14: =IFERROR(SUM(V14:X14),0) -> 0 | Z14: =IFERROR(COUNTIFS(T_Assign[תאריך],Z6,T_Assign[משמרת],"בוקר",T_Assign[מחלקה],$A14),0) -> 0 | AA14: =IFERROR(COUNTIFS(T_Assign[תאריך],Z6,T_Assign[משמרת],"אמצע",T_Assign[מחלקה],$A14),0) -> 0 | AB14: =IFERROR(COUNTIFS(T_Assign[תאריך],Z6,T_Assign[משמרת],"ערב",T_Assign[מחלקה],$A14),0) -> 0 | AC14: =IFERROR(SUM(Z14:AB14),0) -> 0 | AD14: =IFERROR(E14+I14+M14+Q14+U14+Y14+AC14,0) -> 0 | AE14: =IFERROR(SUMPRODUCT((T_Standards[מחלקה]=$A14)*T_Standards[תקן])*7,0) -> 0 | AF14: =IFERROR(AE14-AD14,0) -> 0
A15: =IFERROR(INDEX(T_Depts[מחלקה],8),"") | B15: =IFERROR(COUNTIFS(T_Assign[תאריך],B6,T_Assign[משמרת],"בוקר",T_Assign[מחלקה],$A15),0) -> 0 | C15: =IFERROR(COUNTIFS(T_Assign[תאריך],B6,T_Assign[משמרת],"אמצע",T_Assign[מחלקה],$A15),0) -> 0 | D15: =IFERROR(COUNTIFS(T_Assign[תאריך],B6,T_Assign[משמרת],"ערב",T_Assign[מחלקה],$A15),0) -> 0 | E15: =IFERROR(SUM(B15:D15),0) -> 0 | F15: =IFERROR(COUNTIFS(T_Assign[תאריך],F6,T_Assign[משמרת],"בוקר",T_Assign[מחלקה],$A15),0) -> 0 | G15: =IFERROR(COUNTIFS(T_Assign[תאריך],F6,T_Assign[משמרת],"אמצע",T_Assign[מחלקה],$A15),0) -> 0 | H15: =IFERROR(COUNTIFS(T_Assign[תאריך],F6,T_Assign[משמרת],"ערב",T_Assign[מחלקה],$A15),0) -> 0 | I15: =IFERROR(SUM(F15:H15),0) -> 0 | J15: =IFERROR(COUNTIFS(T_Assign[תאריך],J6,T_Assign[משמרת],"בוקר",T_Assign[מחלקה],$A15),0) -> 0 | K15: =IFERROR(COUNTIFS(T_Assign[תאריך],J6,T_Assign[משמרת],"אמצע",T_Assign[מחלקה],$A15),0) -> 0 | L15: =IFERROR(COUNTIFS(T_Assign[תאריך],J6,T_Assign[משמרת],"ערב",T_Assign[מחלקה],$A15),0) -> 0 | M15: =IFERROR(SUM(J15:L15),0) -> 0 | N15: =IFERROR(COUNTIFS(T_Assign[תאריך],N6,T_Assign[משמרת],"בוקר",T_Assign[מחלקה],$A15),0) -> 0 | O15: =IFERROR(COUNTIFS(T_Assign[תאריך],N6,T_Assign[משמרת],"אמצע",T_Assign[מחלקה],$A15),0) -> 0 | P15: =IFERROR(COUNTIFS(T_Assign[תאריך],N6,T_Assign[משמרת],"ערב",T_Assign[מחלקה],$A15),0) -> 0 | Q15: =IFERROR(SUM(N15:P15),0) -> 0 | R15: =IFERROR(COUNTIFS(T_Assign[תאריך],R6,T_Assign[משמרת],"בוקר",T_Assign[מחלקה],$A15),0) -> 0 | S15: =IFERROR(COUNTIFS(T_Assign[תאריך],R6,T_Assign[משמרת],"אמצע",T_Assign[מחלקה],$A15),0) -> 0 | T15: =IFERROR(COUNTIFS(T_Assign[תאריך],R6,T_Assign[משמרת],"ערב",T_Assign[מחלקה],$A15),0) -> 0 | U15: =IFERROR(SUM(R15:T15),0) -> 0 | V15: =IFERROR(COUNTIFS(T_Assign[תאריך],V6,T_Assign[משמרת],"בוקר",T_Assign[מחלקה],$A15),0) -> 0 | W15: =IFERROR(COUNTIFS(T_Assign[תאריך],V6,T_Assign[משמרת],"אמצע",T_Assign[מחלקה],$A15),0) -> 0 | X15: =IFERROR(COUNTIFS(T_Assign[תאריך],V6,T_Assign[משמרת],"ערב",T_Assign[מחלקה],$A15),0) -> 0 | Y15: =IFERROR(SUM(V15:X15),0) -> 0 | Z15: =IFERROR(COUNTIFS(T_Assign[תאריך],Z6,T_Assign[משמרת],"בוקר",T_Assign[מחלקה],$A15),0) -> 0 | AA15: =IFERROR(COUNTIFS(T_Assign[תאריך],Z6,T_Assign[משמרת],"אמצע",T_Assign[מחלקה],$A15),0) -> 0 | AB15: =IFERROR(COUNTIFS(T_Assign[תאריך],Z6,T_Assign[משמרת],"ערב",T_Assign[מחלקה],$A15),0) -> 0 | AC15: =IFERROR(SUM(Z15:AB15),0) -> 0 | AD15: =IFERROR(E15+I15+M15+Q15+U15+Y15+AC15,0) -> 0 | AE15: =IFERROR(SUMPRODUCT((T_Standards[מחלקה]=$A15)*T_Standards[תקן])*7,0) -> 0 | AF15: =IFERROR(AE15-AD15,0) -> 0
A16: =IFERROR(INDEX(T_Depts[מחלקה],9),"") | B16: =IFERROR(COUNTIFS(T_Assign[תאריך],B6,T_Assign[משמרת],"בוקר",T_Assign[מחלקה],$A16),0) -> 0 | C16: =IFERROR(COUNTIFS(T_Assign[תאריך],B6,T_Assign[משמרת],"אמצע",T_Assign[מחלקה],$A16),0) -> 0 | D16: =IFERROR(COUNTIFS(T_Assign[תאריך],B6,T_Assign[משמרת],"ערב",T_Assign[מחלקה],$A16),0) -> 0 | E16: =IFERROR(SUM(B16:D16),0) -> 0 | F16: =IFERROR(COUNTIFS(T_Assign[תאריך],F6,T_Assign[משמרת],"בוקר",T_Assign[מחלקה],$A16),0) -> 0 | G16: =IFERROR(COUNTIFS(T_Assign[תאריך],F6,T_Assign[משמרת],"אמצע",T_Assign[מחלקה],$A16),0) -> 0 | H16: =IFERROR(COUNTIFS(T_Assign[תאריך],F6,T_Assign[משמרת],"ערב",T_Assign[מחלקה],$A16),0) -> 0 | I16: =IFERROR(SUM(F16:H16),0) -> 0 | J16: =IFERROR(COUNTIFS(T_Assign[תאריך],J6,T_Assign[משמרת],"בוקר",T_Assign[מחלקה],$A16),0) -> 0 | K16: =IFERROR(COUNTIFS(T_Assign[תאריך],J6,T_Assign[משמרת],"אמצע",T_Assign[מחלקה],$A16),0) -> 0 | L16: =IFERROR(COUNTIFS(T_Assign[תאריך],J6,T_Assign[משמרת],"ערב",T_Assign[מחלקה],$A16),0) -> 0 | M16: =IFERROR(SUM(J16:L16),0) -> 0 | N16: =IFERROR(COUNTIFS(T_Assign[תאריך],N6,T_Assign[משמרת],"בוקר",T_Assign[מחלקה],$A16),0) -> 0 | O16: =IFERROR(COUNTIFS(T_Assign[תאריך],N6,T_Assign[משמרת],"אמצע",T_Assign[מחלקה],$A16),0) -> 0 | P16: =IFERROR(COUNTIFS(T_Assign[תאריך],N6,T_Assign[משמרת],"ערב",T_Assign[מחלקה],$A16),0) -> 0 | Q16: =IFERROR(SUM(N16:P16),0) -> 0 | R16: =IFERROR(COUNTIFS(T_Assign[תאריך],R6,T_Assign[משמרת],"בוקר",T_Assign[מחלקה],$A16),0) -> 0 | S16: =IFERROR(COUNTIFS(T_Assign[תאריך],R6,T_Assign[משמרת],"אמצע",T_Assign[מחלקה],$A16),0) -> 0 | T16: =IFERROR(COUNTIFS(T_Assign[תאריך],R6,T_Assign[משמרת],"ערב",T_Assign[מחלקה],$A16),0) -> 0 | U16: =IFERROR(SUM(R16:T16),0) -> 0 | V16: =IFERROR(COUNTIFS(T_Assign[תאריך],V6,T_Assign[משמרת],"בוקר",T_Assign[מחלקה],$A16),0) -> 0 | W16: =IFERROR(COUNTIFS(T_Assign[תאריך],V6,T_Assign[משמרת],"אמצע",T_Assign[מחלקה],$A16),0) -> 0 | X16: =IFERROR(COUNTIFS(T_Assign[תאריך],V6,T_Assign[משמרת],"ערב",T_Assign[מחלקה],$A16),0) -> 0 | Y16: =IFERROR(SUM(V16:X16),0) -> 0 | Z16: =IFERROR(COUNTIFS(T_Assign[תאריך],Z6,T_Assign[משמרת],"בוקר",T_Assign[מחלקה],$A16),0) -> 0 | AA16: =IFERROR(COUNTIFS(T_Assign[תאריך],Z6,T_Assign[משמרת],"אמצע",T_Assign[מחלקה],$A16),0) -> 0 | AB16: =IFERROR(COUNTIFS(T_Assign[תאריך],Z6,T_Assign[משמרת],"ערב",T_Assign[מחלקה],$A16),0) -> 0 | AC16: =IFERROR(SUM(Z16:AB16),0) -> 0 | AD16: =IFERROR(E16+I16+M16+Q16+U16+Y16+AC16,0) -> 0 | AE16: =IFERROR(SUMPRODUCT((T_Standards[מחלקה]=$A16)*T_Standards[תקן])*7,0) -> 0 | AF16: =IFERROR(AE16-AD16,0) -> 0
A17: =IFERROR(INDEX(T_Depts[מחלקה],10),"") | B17: =IFERROR(COUNTIFS(T_Assign[תאריך],B6,T_Assign[משמרת],"בוקר",T_Assign[מחלקה],$A17),0) -> 0 | C17: =IFERROR(COUNTIFS(T_Assign[תאריך],B6,T_Assign[משמרת],"אמצע",T_Assign[מחלקה],$A17),0) -> 0 | D17: =IFERROR(COUNTIFS(T_Assign[תאריך],B6,T_Assign[משמרת],"ערב",T_Assign[מחלקה],$A17),0) -> 0 | E17: =IFERROR(SUM(B17:D17),0) -> 0 | F17: =IFERROR(COUNTIFS(T_Assign[תאריך],F6,T_Assign[משמרת],"בוקר",T_Assign[מחלקה],$A17),0) -> 0 | G17: =IFERROR(COUNTIFS(T_Assign[תאריך],F6,T_Assign[משמרת],"אמצע",T_Assign[מחלקה],$A17),0) -> 0 | H17: =IFERROR(COUNTIFS(T_Assign[תאריך],F6,T_Assign[משמרת],"ערב",T_Assign[מחלקה],$A17),0) -> 0 | I17: =IFERROR(SUM(F17:H17),0) -> 0 | J17: =IFERROR(COUNTIFS(T_Assign[תאריך],J6,T_Assign[משמרת],"בוקר",T_Assign[מחלקה],$A17),0) -> 0 | K17: =IFERROR(COUNTIFS(T_Assign[תאריך],J6,T_Assign[משמרת],"אמצע",T_Assign[מחלקה],$A17),0) -> 0 | L17: =IFERROR(COUNTIFS(T_Assign[תאריך],J6,T_Assign[משמרת],"ערב",T_Assign[מחלקה],$A17),0) -> 0 | M17: =IFERROR(SUM(J17:L17),0) -> 0 | N17: =IFERROR(COUNTIFS(T_Assign[תאריך],N6,T_Assign[משמרת],"בוקר",T_Assign[מחלקה],$A17),0) -> 0 | O17: =IFERROR(COUNTIFS(T_Assign[תאריך],N6,T_Assign[משמרת],"אמצע",T_Assign[מחלקה],$A17),0) -> 0 | P17: =IFERROR(COUNTIFS(T_Assign[תאריך],N6,T_Assign[משמרת],"ערב",T_Assign[מחלקה],$A17),0) -> 0 | Q17: =IFERROR(SUM(N17:P17),0) -> 0 | R17: =IFERROR(COUNTIFS(T_Assign[תאריך],R6,T_Assign[משמרת],"בוקר",T_Assign[מחלקה],$A17),0) -> 0 | S17: =IFERROR(COUNTIFS(T_Assign[תאריך],R6,T_Assign[משמרת],"אמצע",T_Assign[מחלקה],$A17),0) -> 0 | T17: =IFERROR(COUNTIFS(T_Assign[תאריך],R6,T_Assign[משמרת],"ערב",T_Assign[מחלקה],$A17),0) -> 0 | U17: =IFERROR(SUM(R17:T17),0) -> 0 | V17: =IFERROR(COUNTIFS(T_Assign[תאריך],V6,T_Assign[משמרת],"בוקר",T_Assign[מחלקה],$A17),0) -> 0 | W17: =IFERROR(COUNTIFS(T_Assign[תאריך],V6,T_Assign[משמרת],"אמצע",T_Assign[מחלקה],$A17),0) -> 0 | X17: =IFERROR(COUNTIFS(T_Assign[תאריך],V6,T_Assign[משמרת],"ערב",T_Assign[מחלקה],$A17),0) -> 0 | Y17: =IFERROR(SUM(V17:X17),0) -> 0 | Z17: =IFERROR(COUNTIFS(T_Assign[תאריך],Z6,T_Assign[משמרת],"בוקר",T_Assign[מחלקה],$A17),0) -> 0 | AA17: =IFERROR(COUNTIFS(T_Assign[תאריך],Z6,T_Assign[משמרת],"אמצע",T_Assign[מחלקה],$A17),0) -> 0 | AB17: =IFERROR(COUNTIFS(T_Assign[תאריך],Z6,T_Assign[משמרת],"ערב",T_Assign[מחלקה],$A17),0) -> 0 | AC17: =IFERROR(SUM(Z17:AB17),0) -> 0 | AD17: =IFERROR(E17+I17+M17+Q17+U17+Y17+AC17,0) -> 0 | AE17: =IFERROR(SUMPRODUCT((T_Standards[מחלקה]=$A17)*T_Standards[תקן])*7,0) -> 0 | AF17: =IFERROR(AE17-AD17,0) -> 0
A18: =IFERROR(INDEX(T_Depts[מחלקה],11),"") | B18: =IFERROR(COUNTIFS(T_Assign[תאריך],B6,T_Assign[משמרת],"בוקר",T_Assign[מחלקה],$A18),0) -> 0 | C18: =IFERROR(COUNTIFS(T_Assign[תאריך],B6,T_Assign[משמרת],"אמצע",T_Assign[מחלקה],$A18),0) -> 0 | D18: =IFERROR(COUNTIFS(T_Assign[תאריך],B6,T_Assign[משמרת],"ערב",T_Assign[מחלקה],$A18),0) -> 0 | E18: =IFERROR(SUM(B18:D18),0) -> 0 | F18: =IFERROR(COUNTIFS(T_Assign[תאריך],F6,T_Assign[משמרת],"בוקר",T_Assign[מחלקה],$A18),0) -> 0 | G18: =IFERROR(COUNTIFS(T_Assign[תאריך],F6,T_Assign[משמרת],"אמצע",T_Assign[מחלקה],$A18),0) -> 0 | H18: =IFERROR(COUNTIFS(T_Assign[תאריך],F6,T_Assign[משמרת],"ערב",T_Assign[מחלקה],$A18),0) -> 0 | I18: =IFERROR(SUM(F18:H18),0) -> 0 | J18: =IFERROR(COUNTIFS(T_Assign[תאריך],J6,T_Assign[משמרת],"בוקר",T_Assign[מחלקה],$A18),0) -> 0 | K18: =IFERROR(COUNTIFS(T_Assign[תאריך],J6,T_Assign[משמרת],"אמצע",T_Assign[מחלקה],$A18),0) -> 0 | L18: =IFERROR(COUNTIFS(T_Assign[תאריך],J6,T_Assign[משמרת],"ערב",T_Assign[מחלקה],$A18),0) -> 0 | M18: =IFERROR(SUM(J18:L18),0) -> 0 | N18: =IFERROR(COUNTIFS(T_Assign[תאריך],N6,T_Assign[משמרת],"בוקר",T_Assign[מחלקה],$A18),0) -> 0 | O18: =IFERROR(COUNTIFS(T_Assign[תאריך],N6,T_Assign[משמרת],"אמצע",T_Assign[מחלקה],$A18),0) -> 0 | P18: =IFERROR(COUNTIFS(T_Assign[תאריך],N6,T_Assign[משמרת],"ערב",T_Assign[מחלקה],$A18),0) -> 0 | Q18: =IFERROR(SUM(N18:P18),0) -> 0 | R18: =IFERROR(COUNTIFS(T_Assign[תאריך],R6,T_Assign[משמרת],"בוקר",T_Assign[מחלקה],$A18),0) -> 0 | S18: =IFERROR(COUNTIFS(T_Assign[תאריך],R6,T_Assign[משמרת],"אמצע",T_Assign[מחלקה],$A18),0) -> 0 | T18: =IFERROR(COUNTIFS(T_Assign[תאריך],R6,T_Assign[משמרת],"ערב",T_Assign[מחלקה],$A18),0) -> 0 | U18: =IFERROR(SUM(R18:T18),0) -> 0 | V18: =IFERROR(COUNTIFS(T_Assign[תאריך],V6,T_Assign[משמרת],"בוקר",T_Assign[מחלקה],$A18),0) -> 0 | W18: =IFERROR(COUNTIFS(T_Assign[תאריך],V6,T_Assign[משמרת],"אמצע",T_Assign[מחלקה],$A18),0) -> 0 | X18: =IFERROR(COUNTIFS(T_Assign[תאריך],V6,T_Assign[משמרת],"ערב",T_Assign[מחלקה],$A18),0) -> 0 | Y18: =IFERROR(SUM(V18:X18),0) -> 0 | Z18: =IFERROR(COUNTIFS(T_Assign[תאריך],Z6,T_Assign[משמרת],"בוקר",T_Assign[מחלקה],$A18),0) -> 0 | AA18: =IFERROR(COUNTIFS(T_Assign[תאריך],Z6,T_Assign[משמרת],"אמצע",T_Assign[מחלקה],$A18),0) -> 0 | AB18: =IFERROR(COUNTIFS(T_Assign[תאריך],Z6,T_Assign[משמרת],"ערב",T_Assign[מחלקה],$A18),0) -> 0 | AC18: =IFERROR(SUM(Z18:AB18),0) -> 0 | AD18: =IFERROR(E18+I18+M18+Q18+U18+Y18+AC18,0) -> 0 | AE18: =IFERROR(SUMPRODUCT((T_Standards[מחלקה]=$A18)*T_Standards[תקן])*7,0) -> 0 | AF18: =IFERROR(AE18-AD18,0) -> 0
A19: =IFERROR(INDEX(T_Depts[מחלקה],12),"") | B19: =IFERROR(COUNTIFS(T_Assign[תאריך],B6,T_Assign[משמרת],"בוקר",T_Assign[מחלקה],$A19),0) -> 0 | C19: =IFERROR(COUNTIFS(T_Assign[תאריך],B6,T_Assign[משמרת],"אמצע",T_Assign[מחלקה],$A19),0) -> 0 | D19: =IFERROR(COUNTIFS(T_Assign[תאריך],B6,T_Assign[משמרת],"ערב",T_Assign[מחלקה],$A19),0) -> 0 | E19: =IFERROR(SUM(B19:D19),0) -> 0 | F19: =IFERROR(COUNTIFS(T_Assign[תאריך],F6,T_Assign[משמרת],"בוקר",T_Assign[מחלקה],$A19),0) -> 0 | G19: =IFERROR(COUNTIFS(T_Assign[תאריך],F6,T_Assign[משמרת],"אמצע",T_Assign[מחלקה],$A19),0) -> 0 | H19: =IFERROR(COUNTIFS(T_Assign[תאריך],F6,T_Assign[משמרת],"ערב",T_Assign[מחלקה],$A19),0) -> 0 | I19: =IFERROR(SUM(F19:H19),0) -> 0 | J19: =IFERROR(COUNTIFS(T_Assign[תאריך],J6,T_Assign[משמרת],"בוקר",T_Assign[מחלקה],$A19),0) -> 0 | K19: =IFERROR(COUNTIFS(T_Assign[תאריך],J6,T_Assign[משמרת],"אמצע",T_Assign[מחלקה],$A19),0) -> 0 | L19: =IFERROR(COUNTIFS(T_Assign[תאריך],J6,T_Assign[משמרת],"ערב",T_Assign[מחלקה],$A19),0) -> 0 | M19: =IFERROR(SUM(J19:L19),0) -> 0 | N19: =IFERROR(COUNTIFS(T_Assign[תאריך],N6,T_Assign[משמרת],"בוקר",T_Assign[מחלקה],$A19),0) -> 0 | O19: =IFERROR(COUNTIFS(T_Assign[תאריך],N6,T_Assign[משמרת],"אמצע",T_Assign[מחלקה],$A19),0) -> 0 | P19: =IFERROR(COUNTIFS(T_Assign[תאריך],N6,T_Assign[משמרת],"ערב",T_Assign[מחלקה],$A19),0) -> 0 | Q19: =IFERROR(SUM(N19:P19),0) -> 0 | R19: =IFERROR(COUNTIFS(T_Assign[תאריך],R6,T_Assign[משמרת],"בוקר",T_Assign[מחלקה],$A19),0) -> 0 | S19: =IFERROR(COUNTIFS(T_Assign[תאריך],R6,T_Assign[משמרת],"אמצע",T_Assign[מחלקה],$A19),0) -> 0 | T19: =IFERROR(COUNTIFS(T_Assign[תאריך],R6,T_Assign[משמרת],"ערב",T_Assign[מחלקה],$A19),0) -> 0 | U19: =IFERROR(SUM(R19:T19),0) -> 0 | V19: =IFERROR(COUNTIFS(T_Assign[תאריך],V6,T_Assign[משמרת],"בוקר",T_Assign[מחלקה],$A19),0) -> 0 | W19: =IFERROR(COUNTIFS(T_Assign[תאריך],V6,T_Assign[משמרת],"אמצע",T_Assign[מחלקה],$A19),0) -> 0 | X19: =IFERROR(COUNTIFS(T_Assign[תאריך],V6,T_Assign[משמרת],"ערב",T_Assign[מחלקה],$A19),0) -> 0 | Y19: =IFERROR(SUM(V19:X19),0) -> 0 | Z19: =IFERROR(COUNTIFS(T_Assign[תאריך],Z6,T_Assign[משמרת],"בוקר",T_Assign[מחלקה],$A19),0) -> 0 | AA19: =IFERROR(COUNTIFS(T_Assign[תאריך],Z6,T_Assign[משמרת],"אמצע",T_Assign[מחלקה],$A19),0) -> 0 | AB19: =IFERROR(COUNTIFS(T_Assign[תאריך],Z6,T_Assign[משמרת],"ערב",T_Assign[מחלקה],$A19),0) -> 0 | AC19: =IFERROR(SUM(Z19:AB19),0) -> 0 | AD19: =IFERROR(E19+I19+M19+Q19+U19+Y19+AC19,0) -> 0 | AE19: =IFERROR(SUMPRODUCT((T_Standards[מחלקה]=$A19)*T_Standards[תקן])*7,0) -> 0 | AF19: =IFERROR(AE19-AD19,0) -> 0
A20: =IFERROR(INDEX(T_Depts[מחלקה],13),"") | B20: =IFERROR(COUNTIFS(T_Assign[תאריך],B6,T_Assign[משמרת],"בוקר",T_Assign[מחלקה],$A20),0) -> 0 | C20: =IFERROR(COUNTIFS(T_Assign[תאריך],B6,T_Assign[משמרת],"אמצע",T_Assign[מחלקה],$A20),0) -> 0 | D20: =IFERROR(COUNTIFS(T_Assign[תאריך],B6,T_Assign[משמרת],"ערב",T_Assign[מחלקה],$A20),0) -> 0 | E20: =IFERROR(SUM(B20:D20),0) -> 0 | F20: =IFERROR(COUNTIFS(T_Assign[תאריך],F6,T_Assign[משמרת],"בוקר",T_Assign[מחלקה],$A20),0) -> 0 | G20: =IFERROR(COUNTIFS(T_Assign[תאריך],F6,T_Assign[משמרת],"אמצע",T_Assign[מחלקה],$A20),0) -> 0 | H20: =IFERROR(COUNTIFS(T_Assign[תאריך],F6,T_Assign[משמרת],"ערב",T_Assign[מחלקה],$A20),0) -> 0 | I20: =IFERROR(SUM(F20:H20),0) -> 0 | J20: =IFERROR(COUNTIFS(T_Assign[תאריך],J6,T_Assign[משמרת],"בוקר",T_Assign[מחלקה],$A20),0) -> 0 | K20: =IFERROR(COUNTIFS(T_Assign[תאריך],J6,T_Assign[משמרת],"אמצע",T_Assign[מחלקה],$A20),0) -> 0 | L20: =IFERROR(COUNTIFS(T_Assign[תאריך],J6,T_Assign[משמרת],"ערב",T_Assign[מחלקה],$A20),0) -> 0 | M20: =IFERROR(SUM(J20:L20),0) -> 0 | N20: =IFERROR(COUNTIFS(T_Assign[תאריך],N6,T_Assign[משמרת],"בוקר",T_Assign[מחלקה],$A20),0) -> 0 | O20: =IFERROR(COUNTIFS(T_Assign[תאריך],N6,T_Assign[משמרת],"אמצע",T_Assign[מחלקה],$A20),0) -> 0 | P20: =IFERROR(COUNTIFS(T_Assign[תאריך],N6,T_Assign[משמרת],"ערב",T_Assign[מחלקה],$A20),0) -> 0 | Q20: =IFERROR(SUM(N20:P20),0) -> 0 | R20: =IFERROR(COUNTIFS(T_Assign[תאריך],R6,T_Assign[משמרת],"בוקר",T_Assign[מחלקה],$A20),0) -> 0 | S20: =IFERROR(COUNTIFS(T_Assign[תאריך],R6,T_Assign[משמרת],"אמצע",T_Assign[מחלקה],$A20),0) -> 0 | T20: =IFERROR(COUNTIFS(T_Assign[תאריך],R6,T_Assign[משמרת],"ערב",T_Assign[מחלקה],$A20),0) -> 0 | U20: =IFERROR(SUM(R20:T20),0) -> 0 | V20: =IFERROR(COUNTIFS(T_Assign[תאריך],V6,T_Assign[משמרת],"בוקר",T_Assign[מחלקה],$A20),0) -> 0 | W20: =IFERROR(COUNTIFS(T_Assign[תאריך],V6,T_Assign[משמרת],"אמצע",T_Assign[מחלקה],$A20),0) -> 0 | X20: =IFERROR(COUNTIFS(T_Assign[תאריך],V6,T_Assign[משמרת],"ערב",T_Assign[מחלקה],$A20),0) -> 0 | Y20: =IFERROR(SUM(V20:X20),0) -> 0 | Z20: =IFERROR(COUNTIFS(T_Assign[תאריך],Z6,T_Assign[משמרת],"בוקר",T_Assign[מחלקה],$A20),0) -> 0 | AA20: =IFERROR(COUNTIFS(T_Assign[תאריך],Z6,T_Assign[משמרת],"אמצע",T_Assign[מחלקה],$A20),0) -> 0 | AB20: =IFERROR(COUNTIFS(T_Assign[תאריך],Z6,T_Assign[משמרת],"ערב",T_Assign[מחלקה],$A20),0) -> 0 | AC20: =IFERROR(SUM(Z20:AB20),0) -> 0 | AD20: =IFERROR(E20+I20+M20+Q20+U20+Y20+AC20,0) -> 0 | AE20: =IFERROR(SUMPRODUCT((T_Standards[מחלקה]=$A20)*T_Standards[תקן])*7,0) -> 0 | AF20: =IFERROR(AE20-AD20,0) -> 0
A21: =IFERROR(INDEX(T_Depts[מחלקה],14),"") | B21: =IFERROR(COUNTIFS(T_Assign[תאריך],B6,T_Assign[משמרת],"בוקר",T_Assign[מחלקה],$A21),0) -> 0 | C21: =IFERROR(COUNTIFS(T_Assign[תאריך],B6,T_Assign[משמרת],"אמצע",T_Assign[מחלקה],$A21),0) -> 0 | D21: =IFERROR(COUNTIFS(T_Assign[תאריך],B6,T_Assign[משמרת],"ערב",T_Assign[מחלקה],$A21),0) -> 0 | E21: =IFERROR(SUM(B21:D21),0) -> 0 | F21: =IFERROR(COUNTIFS(T_Assign[תאריך],F6,T_Assign[משמרת],"בוקר",T_Assign[מחלקה],$A21),0) -> 0 | G21: =IFERROR(COUNTIFS(T_Assign[תאריך],F6,T_Assign[משמרת],"אמצע",T_Assign[מחלקה],$A21),0) -> 0 | H21: =IFERROR(COUNTIFS(T_Assign[תאריך],F6,T_Assign[משמרת],"ערב",T_Assign[מחלקה],$A21),0) -> 0 | I21: =IFERROR(SUM(F21:H21),0) -> 0 | J21: =IFERROR(COUNTIFS(T_Assign[תאריך],J6,T_Assign[משמרת],"בוקר",T_Assign[מחלקה],$A21),0) -> 0 | K21: =IFERROR(COUNTIFS(T_Assign[תאריך],J6,T_Assign[משמרת],"אמצע",T_Assign[מחלקה],$A21),0) -> 0 | L21: =IFERROR(COUNTIFS(T_Assign[תאריך],J6,T_Assign[משמרת],"ערב",T_Assign[מחלקה],$A21),0) -> 0 | M21: =IFERROR(SUM(J21:L21),0) -> 0 | N21: =IFERROR(COUNTIFS(T_Assign[תאריך],N6,T_Assign[משמרת],"בוקר",T_Assign[מחלקה],$A21),0) -> 0 | O21: =IFERROR(COUNTIFS(T_Assign[תאריך],N6,T_Assign[משמרת],"אמצע",T_Assign[מחלקה],$A21),0) -> 0 | P21: =IFERROR(COUNTIFS(T_Assign[תאריך],N6,T_Assign[משמרת],"ערב",T_Assign[מחלקה],$A21),0) -> 0 | Q21: =IFERROR(SUM(N21:P21),0) -> 0 | R21: =IFERROR(COUNTIFS(T_Assign[תאריך],R6,T_Assign[משמרת],"בוקר",T_Assign[מחלקה],$A21),0) -> 0 | S21: =IFERROR(COUNTIFS(T_Assign[תאריך],R6,T_Assign[משמרת],"אמצע",T_Assign[מחלקה],$A21),0) -> 0 | T21: =IFERROR(COUNTIFS(T_Assign[תאריך],R6,T_Assign[משמרת],"ערב",T_Assign[מחלקה],$A21),0) -> 0 | U21: =IFERROR(SUM(R21:T21),0) -> 0 | V21: =IFERROR(COUNTIFS(T_Assign[תאריך],V6,T_Assign[משמרת],"בוקר",T_Assign[מחלקה],$A21),0) -> 0 | W21: =IFERROR(COUNTIFS(T_Assign[תאריך],V6,T_Assign[משמרת],"אמצע",T_Assign[מחלקה],$A21),0) -> 0 | X21: =IFERROR(COUNTIFS(T_Assign[תאריך],V6,T_Assign[משמרת],"ערב",T_Assign[מחלקה],$A21),0) -> 0 | Y21: =IFERROR(SUM(V21:X21),0) -> 0 | Z21: =IFERROR(COUNTIFS(T_Assign[תאריך],Z6,T_Assign[משמרת],"בוקר",T_Assign[מחלקה],$A21),0) -> 0 | AA21: =IFERROR(COUNTIFS(T_Assign[תאריך],Z6,T_Assign[משמרת],"אמצע",T_Assign[מחלקה],$A21),0) -> 0 | AB21: =IFERROR(COUNTIFS(T_Assign[תאריך],Z6,T_Assign[משמרת],"ערב",T_Assign[מחלקה],$A21),0) -> 0 | AC21: =IFERROR(SUM(Z21:AB21),0) -> 0 | AD21: =IFERROR(E21+I21+M21+Q21+U21+Y21+AC21,0) -> 0 | AE21: =IFERROR(SUMPRODUCT((T_Standards[מחלקה]=$A21)*T_Standards[תקן])*7,0) -> 0 | AF21: =IFERROR(AE21-AD21,0) -> 0
